Workbook
Name ab_condition: Lists!$AE$3:$AE$104
Name ab_dia_act: Lists!$AD$3:$AD$104
Name ab_dia_req: Lists!$T$3:$T$68
Name ab_F: Lists!$Y$3:$Y$104
Name ab_fc: Lists!$AG$3:$AG$104
Name ab_lede: Lists!$Z$3:$Z$104
Name ab_sdc: Lists!$AF$3:$AF$104
Name abt_corner: Lists!$AB$3:$AB$104
Name abt_end: Lists!$AC$3:$AC$104
Name abt_mid: Lists!$AA$3:$AA$104
Name anchor: Lists!$X$3:$X$104
Name ga_gyp: Lists!$AP$3:$AP$53
Name ga_osb: Lists!$AN$3:$AN$53
Name ga_ply: Lists!$AO$3:$AO$53
Name hd_ab: Sheet1!$W$41:$W$66
Name hd_cap: Sheet1!$E$41:$E$66
Name hd_holdown: Sheet1!$V$41:$V$66
Name hd_mark: Sheet1!$C$41:$C$66
Name hd_off: Sheet1!$L$41:$L$66
Name hdoffset: Lists!$V$3:$V$68
Name hdslip: Lists!$S$3:$S$68
Name hdt_dfsp: Lists!$N$3:$N$68
Name hdt_spfhf: Lists!$O$3:$O$68
Name holdown: Lists!$L$3:$L$68
Name num_gyp: Sheet1!$C$12:$C$20
Name num_osb: Sheet1!$C$30:$C$38
Name num_ply: Sheet1!$C$21:$C$29
Name post24: Lists!$P$3:$P$68
Name post26: Lists!$Q$3:$Q$68
Name sheath_assembly: Sheet1!$K$12:$K$38
Name sheath_ecap_asd: Sheet1!$G$12:$G$38
Name sheath_ecap_lrfd: Sheet1!$I$12:$I$38
Name sheath_ga: Sheet1!$J$12:$J$38
Name sheath_mark: Sheet1!$C$12:$C$38
Name sheath_wcap_asd: Sheet1!$F$12:$F$38
Name sheath_wcap_lrfd: Sheet1!$H$12:$H$38
Name sheathing: Lists!$AQ$3:$AQ$53
Name sw0.5: Lists!$AM$3:$AM$53
Name sw0.8: Lists!$AL$3:$AL$53
Name sw0.92: Lists!$M$3:$M$68
Name sw1.0: Lists!$AI$3:$AI$53
Name sw2.0: Lists!$AJ$3:$AJ$53
Name sw2.8: Lists!$AK$3:$AK$53
Name w_global_wind: Sheet2!$H$20:$H$25

Sheet Sheet1
B2: Shear Walls | F2: INDEX(ITEM PROPERTY,MATCH(ITEM SOURCE, ITEM LIST, 0),0)
B4: AB | C4: SDC
B5: YES | C5: Blocked
B6: 12 | C6: Edge Nailing (in o.c.)
B7: 16 | C7: Max Shear Wall Stud Spacing
B8: =IF(B5="YES",1,IF(B6=6,IF(B7=12,1,IF(B7=16,0.8,IF(B7=19.2,0.6,0.5))),IF(B7=12,0.8,IF(B7=16,0.6,IF(B7=19.2,0.5,0.4))))) -> 1 | C8: Cub
B9: 2500 | C9: Concrete Strength at Anchors
F10: Ω=2.0 | G10: Ω=2.8 | H10: φ=0.8 | I10: φ=0.5
B11: Sheathing | C11: Mark | D11: Both Sides? | E11: Vn (plf) | F11: Vaw | G11: Vae | H11: Vuw | I11: Vue | J11: Ga (k/in) | K11: Assembly
B12: Gypboard | C12: 11 | D12: NO | E12: {=IF(K12=0,0,INDEX(sw1.0,MATCH(K12,sheathing,0),0)*IF(D12="yes",2,1))} -> 290 | F12: {=IF(K12=0,0,INDEX(sw2.0,MATCH(K12,sheathing,0),0)*IF(D12="yes",2,1))} -> 133.4 | G12: {=IF(K12=0,0,INDEX(sw2.8,MATCH(K12,sheathing,0),0)*IF(D12="yes",2,1))} -> 95.285714 | H12: {=IF(K12=0,0,INDEX(sw0.8,MATCH(K12,sheathing,0),0)*IF(D12="yes",2,1))} -> 213.44 | I12: {=IF(K12=0,0,INDEX(sw0.5,MATCH(K12,sheathing,0),0)*IF(D12="yes",2,1))} -> 133.4 | J12: {=IF(K12=0,0,INDEX(ga_gyp,MATCH(K12,sheathing,0),0)*IF(D12="yes",2,1))} -> 7.5 | K12: 5/8" blocked gypsum wallboard with 6d cooler nail at 7"oc edge and 7"oc field
C13: 12 | D13: NO | E13: {=IF(K13=0,0,INDEX(sw1.0,MATCH(K13,sheathing,0),0)*IF(D13="yes",2,1))} -> 350 | F13: {=IF(K13=0,0,INDEX(sw2.0,MATCH(K13,sheathing,0),0)*IF(D13="yes",2,1))} -> 161 | G13: {=IF(K13=0,0,INDEX(sw2.8,MATCH(K13,sheathing,0),0)*IF(D13="yes",2,1))} -> 115 | H13: {=IF(K13=0,0,INDEX(sw0.8,MATCH(K13,sheathing,0),0)*IF(D13="yes",2,1))} -> 257.6 | I13: {=IF(K13=0,0,INDEX(sw0.5,MATCH(K13,sheathing,0),0)*IF(D13="yes",2,1))} -> 161 | J13: {=IF(K13=0,0,INDEX(ga_gyp,MATCH(K13,sheathing,0),0)*IF(D13="yes",2,1))} -> 8.5 | K13: 5/8" blocked gypsum wallboard with 6d cooler nail at 4"oc edge and 4"oc field
C14: 13 | D14: NO | E14: {=IF(K14=0,0,INDEX(sw1.0,MATCH(K14,sheathing,0),0)*IF(D14="yes",2,1))} -> 350 | F14: {=IF(K14=0,0,INDEX(sw2.0,MATCH(K14,sheathing,0),0)*IF(D14="yes",2,1))} -> 161 | G14: {=IF(K14=0,0,INDEX(sw2.8,MATCH(K14,sheathing,0),0)*IF(D14="yes",2,1))} -> 115 | H14: {=IF(K14=0,0,INDEX(sw0.8,MATCH(K14,sheathing,0),0)*IF(D14="yes",2,1))} -> 257.6 | I14: {=IF(K14=0,0,INDEX(sw0.5,MATCH(K14,sheathing,0),0)*IF(D14="yes",2,1))} -> 161 | J14: {=IF(K14=0,0,INDEX(ga_gyp,MATCH(K14,sheathing,0),0)*IF(D14="yes",2,1))} -> 8.5 | K14: 5/8" blocked gypsum wallboard with 6d cooler nail at 4"oc edge and 4"oc field
C15: 14 | D15: NO | E15: {=IF(K15=0,0,INDEX(sw1.0,MATCH(K15,sheathing,0),0)*IF(D15="yes",2,1))} -> 0 | F15: {=IF(K15=0,0,INDEX(sw2.0,MATCH(K15,sheathing,0),0)*IF(D15="yes",2,1))} -> 0 | G15: {=IF(K15=0,0,INDEX(sw2.8,MATCH(K15,sheathing,0),0)*IF(D15="yes",2,1))} -> 0 | H15: {=IF(K15=0,0,INDEX(sw0.8,MATCH(K15,sheathing,0),0)*IF(D15="yes",2,1))} -> 0 | I15: {=IF(K15=0,0,INDEX(sw0.5,MATCH(K15,sheathing,0),0)*IF(D15="yes",2,1))} -> 0 | J15: {=IF(K15=0,0,INDEX(ga_gyp,MATCH(K15,sheathing,0),0)*IF(D15="yes",2,1))} -> 0
C16: 15 | D16: NO | E16: {=IF(K16=0,0,INDEX(sw1.0,MATCH(K16,sheathing,0),0)*IF(D16="yes",2,1))} -> 0 | F16: {=IF(K16=0,0,INDEX(sw2.0,MATCH(K16,sheathing,0),0)*IF(D16="yes",2,1))} -> 0 | G16: {=IF(K16=0,0,INDEX(sw2.8,MATCH(K16,sheathing,0),0)*IF(D16="yes",2,1))} -> 0 | H16: {=IF(K16=0,0,INDEX(sw0.8,MATCH(K16,sheathing,0),0)*IF(D16="yes",2,1))} -> 0 | I16: {=IF(K16=0,0,INDEX(sw0.5,MATCH(K16,sheathing,0),0)*IF(D16="yes",2,1))} -> 0 | J16: {=IF(K16=0,0,INDEX(ga_gyp,MATCH(K16,sheathing,0),0)*IF(D16="yes",2,1))} -> 0
C17: 16 | D17: NO | E17: {=IF(K17=0,0,INDEX(sw1.0,MATCH(K17,sheathing,0),0)*IF(D17="yes",2,1))} -> 0 | F17: {=IF(K17=0,0,INDEX(sw2.0,MATCH(K17,sheathing,0),0)*IF(D17="yes",2,1))} -> 0 | G17: {=IF(K17=0,0,INDEX(sw2.8,MATCH(K17,sheathing,0),0)*IF(D17="yes",2,1))} -> 0 | H17: {=IF(K17=0,0,INDEX(sw0.8,MATCH(K17,sheathing,0),0)*IF(D17="yes",2,1))} -> 0 | I17: {=IF(K17=0,0,INDEX(sw0.5,MATCH(K17,sheathing,0),0)*IF(D17="yes",2,1))} -> 0 | J17: {=IF(K17=0,0,INDEX(ga_gyp,MATCH(K17,sheathing,0),0)*IF(D17="yes",2,1))} -> 0
C18: 17 | D18: NO | E18: {=IF(K18=0,0,INDEX(sw1.0,MATCH(K18,sheathing,0),0)*IF(D18="yes",2,1))} -> 0 | F18: {=IF(K18=0,0,INDEX(sw2.0,MATCH(K18,sheathing,0),0)*IF(D18="yes",2,1))} -> 0 | G18: {=IF(K18=0,0,INDEX(sw2.8,MATCH(K18,sheathing,0),0)*IF(D18="yes",2,1))} -> 0 | H18: {=IF(K18=0,0,INDEX(sw0.8,MATCH(K18,sheathing,0),0)*IF(D18="yes",2,1))} -> 0 | I18: {=IF(K18=0,0,INDEX(sw0.5,MATCH(K18,sheathing,0),0)*IF(D18="yes",2,1))} -> 0 | J18: {=IF(K18=0,0,INDEX(ga_gyp,MATCH(K18,sheathing,0),0)*IF(D18="yes",2,1))} -> 0
C19: 18 | D19: NO | E19: {=IF(K19=0,0,INDEX(sw1.0,MATCH(K19,sheathing,0),0)*IF(D19="yes",2,1))} -> 0 | F19: {=IF(K19=0,0,INDEX(sw2.0,MATCH(K19,sheathing,0),0)*IF(D19="yes",2,1))} -> 0 | G19: {=IF(K19=0,0,INDEX(sw2.8,MATCH(K19,sheathing,0),0)*IF(D19="yes",2,1))} -> 0 | H19: {=IF(K19=0,0,INDEX(sw0.8,MATCH(K19,sheathing,0),0)*IF(D19="yes",2,1))} -> 0 | I19: {=IF(K19=0,0,INDEX(sw0.5,MATCH(K19,sheathing,0),0)*IF(D19="yes",2,1))} -> 0 | J19: {=IF(K19=0,0,INDEX(ga_gyp,MATCH(K19,sheathing,0),0)*IF(D19="yes",2,1))} -> 0
C20: 19 | D20: NO | E20: {=IF(K20=0,0,INDEX(sw1.0,MATCH(K20,sheathing,0),0)*IF(D20="yes",2,1))} -> 0 | F20: {=IF(K20=0,0,INDEX(sw2.0,MATCH(K20,sheathing,0),0)*IF(D20="yes",2,1))} -> 0 | G20: {=IF(K20=0,0,INDEX(sw2.8,MATCH(K20,sheathing,0),0)*IF(D20="yes",2,1))} -> 0 | H20: {=IF(K20=0,0,INDEX(sw0.8,MATCH(K20,sheathing,0),0)*IF(D20="yes",2,1))} -> 0 | I20: {=IF(K20=0,0,INDEX(sw0.5,MATCH(K20,sheathing,0),0)*IF(D20="yes",2,1))} -> 0 | J20: {=IF(K20=0,0,INDEX(ga_gyp,MATCH(K20,sheathing,0),0)*IF(D20="yes",2,1))} -> 0
B21: Plywood | C21: 21 | D21: NO | E21: {=IF(K21=0,0,INDEX(sw1.0,MATCH(K21,sheathing,0),0)*IF(D21="yes",2,1))} -> 730 | F21: {=IF(K21=0,0,INDEX(sw2.0,MATCH(K21,sheathing,0),0)*IF(D21="yes",2,1))} -> 335.8 | G21: {=IF(K21=0,0,INDEX(sw2.8,MATCH(K21,sheathing,0),0)*IF(D21="yes",2,1))} -> 239.85714 | H21: {=IF(K21=0,0,INDEX(sw0.8,MATCH(K21,sheathing,0),0)*IF(D21="yes",2,1))} -> 537.28 | I21: {=IF(K21=0,0,INDEX(sw0.5,MATCH(K21,sheathing,0),0)*IF(D21="yes",2,1))} -> 335.8 | J21: {=IF(K21=0,0,INDEX(ga_ply,MATCH(K21,sheathing,0),0)*IF(D21="yes",2,1))} -> 10 | K21: 3/8" (7/16 or 15/32) blocked WSP sheathing with 8d at 6"oc edge and 12"oc field
B22: (or OSB) | C22: 22 | D22: NO | E22: {=IF(K22=0,0,INDEX(sw1.0,MATCH(K22,sheathing,0),0)*IF(D22="yes",2,1))} -> 1065 | F22: {=IF(K22=0,0,INDEX(sw2.0,MATCH(K22,sheathing,0),0)*IF(D22="yes",2,1))} -> 489.9 | G22: {=IF(K22=0,0,INDEX(sw2.8,MATCH(K22,sheathing,0),0)*IF(D22="yes",2,1))} -> 349.92857 | H22: {=IF(K22=0,0,INDEX(sw0.8,MATCH(K22,sheathing,0),0)*IF(D22="yes",2,1))} -> 783.84 | I22: {=IF(K22=0,0,INDEX(sw0.5,MATCH(K22,sheathing,0),0)*IF(D22="yes",2,1))} -> 489.9 | J22: {=IF(K22=0,0,INDEX(ga_ply,MATCH(K22,sheathing,0),0)*IF(D22="yes",2,1))} -> 13 | K22: 3/8" (7/16 or 15/32) blocked WSP sheathing with 8d at 4"oc edge and 12"oc field
C23: 23 | D23: NO | E23: {=IF(K23=0,0,INDEX(sw1.0,MATCH(K23,sheathing,0),0)*IF(D23="yes",2,1))} -> 1370 | F23: {=IF(K23=0,0,INDEX(sw2.0,MATCH(K23,sheathing,0),0)*IF(D23="yes",2,1))} -> 630.2 | G23: {=IF(K23=0,0,INDEX(sw2.8,MATCH(K23,sheathing,0),0)*IF(D23="yes",2,1))} -> 450.14286 | H23: {=IF(K23=0,0,INDEX(sw0.8,MATCH(K23,sheathing,0),0)*IF(D23="yes",2,1))} -> 1008.32 | I23: {=IF(K23=0,0,INDEX(sw0.5,MATCH(K23,sheathing,0),0)*IF(D23="yes",2,1))} -> 630.2 | J23: {=IF(K23=0,0,INDEX(ga_ply,MATCH(K23,sheathing,0),0)*IF(D23="yes",2,1))} -> 15 | K23: 3/8" (7/16 or 15/32) blocked WSP sheathing with 8d at 3"oc edge and 12"oc field
C24: 24 | D24: NO | E24: {=IF(K24=0,0,INDEX(sw1.0,MATCH(K24,sheathing,0),0)*IF(D24="yes",2,1))} -> 1790 | F24: {=IF(K24=0,0,INDEX(sw2.0,MATCH(K24,sheathing,0),0)*IF(D24="yes",2,1))} -> 823.4 | G24: {=IF(K24=0,0,INDEX(sw2.8,MATCH(K24,sheathing,0),0)*IF(D24="yes",2,1))} -> 588.14286 | H24: {=IF(K24=0,0,INDEX(sw0.8,MATCH(K24,sheathing,0),0)*IF(D24="yes",2,1))} -> 1317.44 | I24: {=IF(K24=0,0,INDEX(sw0.5,MATCH(K24,sheathing,0),0)*IF(D24="yes",2,1))} -> 823.4 | J24: {=IF(K24=0,0,INDEX(ga_ply,MATCH(K24,sheathing,0),0)*IF(D24="yes",2,1))} -> 20 | K24: 3/8" (7/16 or 15/32) blocked WSP sheathing with 8d at 2"oc edge and 12"oc field
C25: 25 | D25: NO | E25: {=IF(K25=0,0,INDEX(sw1.0,MATCH(K25,sheathing,0),0)*IF(D25="yes",2,1))} -> 0 | F25: {=IF(K25=0,0,INDEX(sw2.0,MATCH(K25,sheathing,0),0)*IF(D25="yes",2,1))} -> 0 | G25: {=IF(K25=0,0,INDEX(sw2.8,MATCH(K25,sheathing,0),0)*IF(D25="yes",2,1))} -> 0 | H25: {=IF(K25=0,0,INDEX(sw0.8,MATCH(K25,sheathing,0),0)*IF(D25="yes",2,1))} -> 0 | I25: {=IF(K25=0,0,INDEX(sw0.5,MATCH(K25,sheathing,0),0)*IF(D25="yes",2,1))} -> 0 | J25: {=IF(K25=0,0,INDEX(ga_ply,MATCH(K25,sheathing,0),0)*IF(D25="yes",2,1))} -> 0
C26: 26 | D26: NO | E26: {=IF(K26=0,0,INDEX(sw1.0,MATCH(K26,sheathing,0),0)*IF(D26="yes",2,1))} -> 0 | F26: {=IF(K26=0,0,INDEX(sw2.0,MATCH(K26,sheathing,0),0)*IF(D26="yes",2,1))} -> 0 | G26: {=IF(K26=0,0,INDEX(sw2.8,MATCH(K26,sheathing,0),0)*IF(D26="yes",2,1))} -> 0 | H26: {=IF(K26=0,0,INDEX(sw0.8,MATCH(K26,sheathing,0),0)*IF(D26="yes",2,1))} -> 0 | I26: {=IF(K26=0,0,INDEX(sw0.5,MATCH(K26,sheathing,0),0)*IF(D26="yes",2,1))} -> 0 | J26: {=IF(K26=0,0,INDEX(ga_ply,MATCH(K26,sheathing,0),0)*IF(D26="yes",2,1))} -> 0
C27: 27 | D27: NO | E27: {=IF(K27=0,0,INDEX(sw1.0,MATCH(K27,sheathing,0),0)*IF(D27="yes",2,1))} -> 0 | F27: {=IF(K27=0,0,INDEX(sw2.0,MATCH(K27,sheathing,0),0)*IF(D27="yes",2,1))} -> 0 | G27: {=IF(K27=0,0,INDEX(sw2.8,MATCH(K27,sheathing,0),0)*IF(D27="yes",2,1))} -> 0 | H27: {=IF(K27=0,0,INDEX(sw0.8,MATCH(K27,sheathing,0),0)*IF(D27="yes",2,1))} -> 0 | I27: {=IF(K27=0,0,INDEX(sw0.5,MATCH(K27,sheathing,0),0)*IF(D27="yes",2,1))} -> 0 | J27: {=IF(K27=0,0,INDEX(ga_ply,MATCH(K27,sheathing,0),0)*IF(D27="yes",2,1))} -> 0
C28: 28 | D28: NO | E28: {=IF(K28=0,0,INDEX(sw1.0,MATCH(K28,sheathing,0),0)*IF(D28="yes",2,1))} -> 0 | F28: {=IF(K28=0,0,INDEX(sw2.0,MATCH(K28,sheathing,0),0)*IF(D28="yes",2,1))} -> 0 | G28: {=IF(K28=0,0,INDEX(sw2.8,MATCH(K28,sheathing,0),0)*IF(D28="yes",2,1))} -> 0 | H28: {=IF(K28=0,0,INDEX(sw0.8,MATCH(K28,sheathing,0),0)*IF(D28="yes",2,1))} -> 0 | I28: {=IF(K28=0,0,INDEX(sw0.5,MATCH(K28,sheathing,0),0)*IF(D28="yes",2,1))} -> 0 | J28: {=IF(K28=0,0,INDEX(ga_ply,MATCH(K28,sheathing,0),0)*IF(D28="yes",2,1))} -> 0
C29: 29 | D29: NO | E29: {=IF(K29=0,0,INDEX(sw1.0,MATCH(K29,sheathing,0),0)*IF(D29="yes",2,1))} -> 0 | F29: {=IF(K29=0,0,INDEX(sw2.0,MATCH(K29,sheathing,0),0)*IF(D29="yes",2,1))} -> 0 | G29: {=IF(K29=0,0,INDEX(sw2.8,MATCH(K29,sheathing,0),0)*IF(D29="yes",2,1))} -> 0 | H29: {=IF(K29=0,0,INDEX(sw0.8,MATCH(K29,sheathing,0),0)*IF(D29="yes",2,1))} -> 0 | I29: {=IF(K29=0,0,INDEX(sw0.5,MATCH(K29,sheathing,0),0)*IF(D29="yes",2,1))} -> 0 | J29: {=IF(K29=0,0,INDEX(ga_ply,MATCH(K29,sheathing,0),0)*IF(D29="yes",2,1))} -> 0
B30: OSB | C30: 31 | D30: NO | E30: {=IF(K30=0,0,INDEX(sw1.0,MATCH(K30,sheathing,0),0)*IF(D30="yes",2,1))} -> 730 | F30: {=IF(K30=0,0,INDEX(sw2.0,MATCH(K30,sheathing,0),0)*IF(D30="yes",2,1))} -> 335.8 | G30: {=IF(K30=0,0,INDEX(sw2.8,MATCH(K30,sheathing,0),0)*IF(D30="yes",2,1))} -> 239.85714 | H30: {=IF(K30=0,0,INDEX(sw0.8,MATCH(K30,sheathing,0),0)*IF(D30="yes",2,1))} -> 537.28 | I30: {=IF(K30=0,0,INDEX(sw0.5,MATCH(K30,sheathing,0),0)*IF(D30="yes",2,1))} -> 335.8 | J30: {=IF(K30=0,0,INDEX(ga_osb,MATCH(K30,sheathing,0),0)*IF(D30="yes",2,1))} -> 13 | K30: 3/8" (7/16 or 15/32) blocked WSP sheathing with 8d at 6"oc edge and 12"oc field
C31: 32 | D31: NO | E31: {=IF(K31=0,0,INDEX(sw1.0,MATCH(K31,sheathing,0),0)*IF(D31="yes",2,1))} -> 1065 | F31: {=IF(K31=0,0,INDEX(sw2.0,MATCH(K31,sheathing,0),0)*IF(D31="yes",2,1))} -> 489.9 | G31: {=IF(K31=0,0,INDEX(sw2.8,MATCH(K31,sheathing,0),0)*IF(D31="yes",2,1))} -> 349.92857 | H31: {=IF(K31=0,0,INDEX(sw0.8,MATCH(K31,sheathing,0),0)*IF(D31="yes",2,1))} -> 783.84 | I31: {=IF(K31=0,0,INDEX(sw0.5,MATCH(K31,sheathing,0),0)*IF(D31="yes",2,1))} -> 489.9 | J31: {=IF(K31=0,0,INDEX(ga_osb,MATCH(K31,sheathing,0),0)*IF(D31="yes",2,1))} -> 19 | K31: 3/8" (7/16 or 15/32) blocked WSP sheathing with 8d at 4"oc edge and 12"oc field
C32: 33 | D32: NO | E32: {=IF(K32=0,0,INDEX(sw1.0,MATCH(K32,sheathing,0),0)*IF(D32="yes",2,1))} -> 1370 | F32: {=IF(K32=0,0,INDEX(sw2.0,MATCH(K32,sheathing,0),0)*IF(D32="yes",2,1))} -> 630.2 | G32: {=IF(K32=0,0,INDEX(sw2.8,MATCH(K32,sheathing,0),0)*IF(D32="yes",2,1))} -> 450.14286 | H32: {=IF(K32=0,0,INDEX(sw0.8,MATCH(K32,sheathing,0),0)*IF(D32="yes",2,1))} -> 1008.32 | I32: {=IF(K32=0,0,INDEX(sw0.5,MATCH(K32,sheathing,0),0)*IF(D32="yes",2,1))} -> 630.2 | J32: {=IF(K32=0,0,INDEX(ga_osb,MATCH(K32,sheathing,0),0)*IF(D32="yes",2,1))} -> 25 | K32: 3/8" (7/16 or 15/32) blocked WSP sheathing with 8d at 3"oc edge and 12"oc field
C33: 34 | D33: NO | E33: {=IF(K33=0,0,INDEX(sw1.0,MATCH(K33,sheathing,0),0)*IF(D33="yes",2,1))} -> 1790 | F33: {=IF(K33=0,0,INDEX(sw2.0,MATCH(K33,sheathing,0),0)*IF(D33="yes",2,1))} -> 823.4 | G33: {=IF(K33=0,0,INDEX(sw2.8,MATCH(K33,sheathing,0),0)*IF(D33="yes",2,1))} -> 588.14286 | H33: {=IF(K33=0,0,INDEX(sw0.8,MATCH(K33,sheathing,0),0)*IF(D33="yes",2,1))} -> 1317.44 | I33: {=IF(K33=0,0,INDEX(sw0.5,MATCH(K33,sheathing,0),0)*IF(D33="yes",2,1))} -> 823.4 | J33: {=IF(K33=0,0,INDEX(ga_osb,MATCH(K33,sheathing,0),0)*IF(D33="yes",2,1))} -> 39 | K33: 3/8" (7/16 or 15/32) blocked WSP sheathing with 8d at 2"oc edge and 12"oc field
C34: 35 | D34: NO | E34: {=IF(K34=0,0,INDEX(sw1.0,MATCH(K34,sheathing,0),0)*IF(D34="yes",2,1))} -> 0 | F34: {=IF(K34=0,0,INDEX(sw2.0,MATCH(K34,sheathing,0),0)*IF(D34="yes",2,1))} -> 0 | G34: {=IF(K34=0,0,INDEX(sw2.8,MATCH(K34,sheathing,0),0)*IF(D34="yes",2,1))} -> 0 | H34: {=IF(K34=0,0,INDEX(sw0.8,MATCH(K34,sheathing,0),0)*IF(D34="yes",2,1))} -> 0 | I34: {=IF(K34=0,0,INDEX(sw0.5,MATCH(K34,sheathing,0),0)*IF(D34="yes",2,1))} -> 0 | J34: {=IF(K34=0,0,INDEX(ga_osb,MATCH(K34,sheathing,0),0)*IF(D34="yes",2,1))} -> 0
C35: 36 | D35: NO | E35: {=IF(K35=0,0,INDEX(sw1.0,MATCH(K35,sheathing,0),0)*IF(D35="yes",2,1))} -> 0 | F35: {=IF(K35=0,0,INDEX(sw2.0,MATCH(K35,sheathing,0),0)*IF(D35="yes",2,1))} -> 0 | G35: {=IF(K35=0,0,INDEX(sw2.8,MATCH(K35,sheathing,0),0)*IF(D35="yes",2,1))} -> 0 | H35: {=IF(K35=0,0,INDEX(sw0.8,MATCH(K35,sheathing,0),0)*IF(D35="yes",2,1))} -> 0 | I35: {=IF(K35=0,0,INDEX(sw0.5,MATCH(K35,sheathing,0),0)*IF(D35="yes",2,1))} -> 0 | J35: {=IF(K35=0,0,INDEX(ga_osb,MATCH(K35,sheathing,0),0)*IF(D35="yes",2,1))} -> 0
C36: 37 | D36: NO | E36: {=IF(K36=0,0,INDEX(sw1.0,MATCH(K36,sheathing,0),0)*IF(D36="yes",2,1))} -> 0 | F36: {=IF(K36=0,0,INDEX(sw2.0,MATCH(K36,sheathing,0),0)*IF(D36="yes",2,1))} -> 0 | G36: {=IF(K36=0,0,INDEX(sw2.8,MATCH(K36,sheathing,0),0)*IF(D36="yes",2,1))} -> 0 | H36: {=IF(K36=0,0,INDEX(sw0.8,MATCH(K36,sheathing,0),0)*IF(D36="yes",2,1))} -> 0 | I36: {=IF(K36=0,0,INDEX(sw0.5,MATCH(K36,sheathing,0),0)*IF(D36="yes",2,1))} -> 0 | J36: {=IF(K36=0,0,INDEX(ga_osb,MATCH(K36,sheathing,0),0)*IF(D36="yes",2,1))} -> 0
C37: 38 | D37: NO | E37: {=IF(K37=0,0,INDEX(sw1.0,MATCH(K37,sheathing,0),0)*IF(D37="yes",2,1))} -> 0 | F37: {=IF(K37=0,0,INDEX(sw2.0,MATCH(K37,sheathing,0),0)*IF(D37="yes",2,1))} -> 0 | G37: {=IF(K37=0,0,INDEX(sw2.8,MATCH(K37,sheathing,0),0)*IF(D37="yes",2,1))} -> 0 | H37: {=IF(K37=0,0,INDEX(sw0.8,MATCH(K37,sheathing,0),0)*IF(D37="yes",2,1))} -> 0 | I37: {=IF(K37=0,0,INDEX(sw0.5,MATCH(K37,sheathing,0),0)*IF(D37="yes",2,1))} -> 0 | J37: {=IF(K37=0,0,INDEX(ga_osb,MATCH(K37,sheathing,0),0)*IF(D37="yes",2,1))} -> 0
C38: 39 | D38: NO | E38: {=IF(K38=0,0,INDEX(sw1.0,MATCH(K38,sheathing,0),0)*IF(D38="yes",2,1))} -> 0 | F38: {=IF(K38=0,0,INDEX(sw2.0,MATCH(K38,sheathing,0),0)*IF(D38="yes",2,1))} -> 0 | G38: {=IF(K38=0,0,INDEX(sw2.8,MATCH(K38,sheathing,0),0)*IF(D38="yes",2,1))} -> 0 | H38: {=IF(K38=0,0,INDEX(sw0.8,MATCH(K38,sheathing,0),0)*IF(D38="yes",2,1))} -> 0 | I38: {=IF(K38=0,0,INDEX(sw0.5,MATCH(K38,sheathing,0),0)*IF(D38="yes",2,1))} -> 0 | J38: {=IF(K38=0,0,INDEX(ga_osb,MATCH(K38,sheathing,0),0)*IF(D38="yes",2,1))} -> 0
B40: Holdown | C40: Mark | D40: Double? | E40: HD Cap | F40: AB Mid | G40: AB Corner | H40: AB End | I40: 2x4 Post | J40: 2x6 Post | K40: Slip | L40: Total Offset | M40: Req AB Dia | N40: AB Dia | O40: AB f'c | P40: AB F | Q40: AB le/de | R40: AB SDC | S40: Condition | T40: 0.92 sw | V40: Holdown | W40: Anchor
C41: A | D41: NO | E41: {=IF(V41=0,0,IF(D41="YES",2,1)*INDEX(IF(OR(Sheet2!$C$12=Lists!$B$25,Sheet2!$C$12=Lists!$B$26,Sheet2!$C$12=Lists!$B$27,Sheet2!$C$12=Lists!$B$28,Sheet2!$C$12=Lists!$B$33,Sheet2!$C$12=Lists!$B$34,Sheet2!$C$12=Lists!$B$35,Sheet2!$C$12=Lists!$B$36),hdt_dfsp,hdt_spfhf),MATCH(V41,holdown,0),0))} -> 2145 | F41: {=IF(W41=0,0,INDEX(abt_mid,MATCH(W41,anchor,0),0))} -> 4270 | G41: {=IF(W41=0,0,INDEX(abt_corner,MATCH(W41,anchor,0),0))} -> 0 | H41: {=IF(W41=0,0,INDEX(abt_end,MATCH(W41,anchor,0),0))} -> 0 | I41: {=IF(V41=0,0,INDEX(post24,MATCH(V41,holdown,0),0))} -> 2-2x4 | J41: {=IF(V41=0,0,INDEX(post26,MATCH(V41,holdown,0),0))} -> 2-2x6 | K41: {=IF(V41=0,0,INDEX(hdslip,MATCH(V41,holdown,0),0))} -> 0.128 | L41: {=IF(V41=0,0,INDEX(hdoffset,MATCH(V41,holdown,0),0))} -> 3.8125 | M41: {=IF(V41=0,0,INDEX(ab_dia_req,MATCH(V41,holdown,0),0))} -> 0.5 | N41: {=IF(W41=0,0,INDEX(ab_dia_act,MATCH(W41,anchor,0),0))} -> 0.5 | O41: {=IF(W41=0,0,INDEX(ab_fc,MATCH(W41,anchor,0),0))} -> 2500 | P41: {=IF(W41=0,0,INDEX(ab_F,MATCH(W41,anchor,0),0))} -> 8 | Q41: {=IF(W41=0,0,INDEX(ab_lede,MATCH(W41,anchor,0),0))} -> 4.5 | R41: {=IF(W41=0,0,INDEX(ab_sdc,MATCH(W41,anchor,0),0))} -> AB | S41: {=IF(W41=0,0,INDEX(ab_condition,MATCH(W41,anchor,0),0))} -> footing | T41: {=IF(V41=0,0,INDEX(sw0.92,MATCH(V41,holdown,0),0))} -> YES | V41: DTT2Z-SDS2.5 | W41: PAB4 (a) | Y41: =IF(V41=0,"",IF(AND(OR(R41=$B$4,R41=0),OR(O41=$B$9,O41=0),OR(N41=M41,N41=0),OR(F41=0,F41>E41,G41>E41,H41>E41)),"OK!","REVISE HD+AB")) -> OK!
C42: B | D42: NO | E42: {=IF(V42=0,0,IF(D42="YES",2,1)*INDEX(IF(OR(Sheet2!$C$12=Lists!$B$25,Sheet2!$C$12=Lists!$B$26,Sheet2!$C$12=Lists!$B$27,Sheet2!$C$12=Lists!$B$28,Sheet2!$C$12=Lists!$B$33,Sheet2!$C$12=Lists!$B$34,Sheet2!$C$12=Lists!$B$35,Sheet2!$C$12=Lists!$B$36),hdt_dfsp,hdt_spfhf),MATCH(V42,holdown,0),0))} -> 3790 | F42: {=IF(W42=0,0,INDEX(abt_mid,MATCH(W42,anchor,0),0))} -> 5535 | G42: {=IF(W42=0,0,INDEX(abt_corner,MATCH(W42,anchor,0),0))} -> 0 | H42: {=IF(W42=0,0,INDEX(abt_end,MATCH(W42,anchor,0),0))} -> 0 | I42: {=IF(V42=0,0,INDEX(post24,MATCH(V42,holdown,0),0))} -> 2-2x4 | J42: {=IF(V42=0,0,INDEX(post26,MATCH(V42,holdown,0),0))} -> 2-2x6 | K42: {=IF(V42=0,0,INDEX(hdslip,MATCH(V42,holdown,0),0))} -> 0.127 | L42: {=IF(V42=0,0,INDEX(hdoffset,MATCH(V42,holdown,0),0))} -> 4.375 | M42: {=IF(V42=0,0,INDEX(ab_dia_req,MATCH(V42,holdown,0),0))} -> 0.625 | N42: {=IF(W42=0,0,INDEX(ab_dia_act,MATCH(W42,anchor,0),0))} -> 0.625 | O42: {=IF(W42=0,0,INDEX(ab_fc,MATCH(W42,anchor,0),0))} -> 2500 | P42: {=IF(W42=0,0,INDEX(ab_F,MATCH(W42,anchor,0),0))} -> 4 | Q42: {=IF(W42=0,0,INDEX(ab_lede,MATCH(W42,anchor,0),0))} -> 7.5 | R42: {=IF(W42=0,0,INDEX(ab_sdc,MATCH(W42,anchor,0),0))} -> AB | S42: {=IF(W42=0,0,INDEX(ab_condition,MATCH(W42,anchor,0),0))} -> footing | T42: {=IF(V42=0,0,INDEX(sw0.92,MATCH(V42,holdown,0),0))} -> YES | V42: HDUE3-SDS3 | W42: PAB5 (a) | Y42: =IF(V42=0,"",IF(AND(OR(R42=$B$4,R42=0),OR(O42=$B$9,O42=0),OR(N42=M42,N42=0),OR(F42=0,F42>E42,G42>E42,H42>E42)),"OK!","REVISE HD+AB")) -> OK!
C43: C | D43: NO | E43: {=IF(V43=0,0,IF(D43="YES",2,1)*INDEX(IF(OR(Sheet2!$C$12=Lists!$B$25,Sheet2!$C$12=Lists!$B$26,Sheet2!$C$12=Lists!$B$27,Sheet2!$C$12=Lists!$B$28,Sheet2!$C$12=Lists!$B$33,Sheet2!$C$12=Lists!$B$34,Sheet2!$C$12=Lists!$B$35,Sheet2!$C$12=Lists!$B$36),hdt_dfsp,hdt_spfhf),MATCH(V43,holdown,0),0))} -> 5375 | F43: {=IF(W43=0,0,INDEX(abt_mid,MATCH(W43,anchor,0),0))} -> 5535 | G43: {=IF(W43=0,0,INDEX(abt_corner,MATCH(W43,anchor,0),0))} -> 0 | H43: {=IF(W43=0,0,INDEX(abt_end,MATCH(W43,anchor,0),0))} -> 0 | I43: {=IF(V43=0,0,INDEX(post24,MATCH(V43,holdown,0),0))} -> 2-2x4 | J43: {=IF(V43=0,0,INDEX(post26,MATCH(V43,holdown,0),0))} -> 2-2x6 | K43: {=IF(V43=0,0,INDEX(hdslip,MATCH(V43,holdown,0),0))} -> 0.146 | L43: {=IF(V43=0,0,INDEX(hdoffset,MATCH(V43,holdown,0),0))} -> 4.375 | M43: {=IF(V43=0,0,INDEX(ab_dia_req,MATCH(V43,holdown,0),0))} -> 0.625 | N43: {=IF(W43=0,0,INDEX(ab_dia_act,MATCH(W43,anchor,0),0))} -> 0.625 | O43: {=IF(W43=0,0,INDEX(ab_fc,MATCH(W43,anchor,0),0))} -> 2500 | P43: {=IF(W43=0,0,INDEX(ab_F,MATCH(W43,anchor,0),0))} -> 4 | Q43: {=IF(W43=0,0,INDEX(ab_lede,MATCH(W43,anchor,0),0))} -> 7.5 | R43: {=IF(W43=0,0,INDEX(ab_sdc,MATCH(W43,anchor,0),0))} -> AB | S43: {=IF(W43=0,0,INDEX(ab_condition,MATCH(W43,anchor,0),0))} -> footing | T43: {=IF(V43=0,0,INDEX(sw0.92,MATCH(V43,holdown,0),0))} -> YES | V43: HDUE5-SDS3 | W43: PAB5 (a) | Y43: =IF(V43=0,"",IF(AND(OR(R43=$B$4,R43=0),OR(O43=$B$9,O43=0),OR(N43=M43,N43=0),OR(F43=0,F43>E43,G43>E43,H43>E43)),"OK!","REVISE HD+AB")) -> OK!
...

Sheet Sheet2
B2: Project Name
B3: Project Number
B4: Date
B6: Building Type
B7: Building Number
B9: Fire Rated Assembly
B10: Fire Retardant Treated Lumber
B12: Lumber Grade | C12: DFL #2 | F12: 1.0-(0.5-Ga) = | G12: =1-(0.5-Sheet1!#REF!) -> #REF!
B13: Single or Double Bot Plate | C13: single | P13: INDEX(ITEM PROPERTY,MATCH(ITEM SOURCE, ITEM LIST, 0),0)
B14: Floor Framing Depth | C14: 18
B15: Floor Sheathing Thickness | C15: 0.75 | E15: heal (in) | F15: low roof | G15: high roof | H15: avg (ft)
B16: Mean Roof Framing Depth | C16: =E16+H16*12 -> 32.4375 | E16: 24 | F16: =32+5.625/12 -> 32.46875 | G16: =33+10.5/12 -> 33.875 | H16: =(G16-F16)/2 -> 0.703125 | Q16: Line | R16: =$B$42 -> A | AT16: Line | AU16: =H42 -> 1
B17: Roof Framing Sheathing | C17: 0.5
R18: left | Z18: right | AH18: user add | AJ18: total | AU18: left | BC18: right | BK18: user add | BM18: total
B19: Heights | C19: ft | D19: in | E19: total | F19: stud | H19: MWFRS (1.0W) | J19: SFRS (1.0E) | R19: w 1.0W | S19: w 0.6W | T19: V 1.0W | U19: V 0.6W | V19: w 1.0E | W19: w 0.7E | X19: V 1.0E | Y19: V 0.7E | Z19: w 1.0W | AA19: w 0.6W | AB19: V 1.0W | AC19: V 0.6W | AD19: w 1.0E | AE19: w 0.7E | AF19: V 1.0E | AG19: V 0.7E | AH19: 1.0W | AI19: 1.0E | AJ19: V 1.0W | AK19: cumm | AL19: V 0.6W | AM19: cumm | AN19: V 1.0E | AO19: cumm | AP19: V 0.7E | AQ19: cumm | AU19: w 1.0W | AV19: w 0.6W | AW19: V 1.0W | AX19: V 0.6W | AY19: w 1.0E | AZ19: w 0.7E | BA19: V 1.0E | BB19: V 0.7E | BC19: w 1.0W | BD19: w 0.6W | BE19: V 1.0W | BF19: V 0.6W | BG19: w 1.0E | BH19: w 0.7E | BI19: V 1.0E | BJ19: V 0.7E | BK19: 1.0W | BL19: 1.0E | BM19: V 1.0W | BN19: cumm | BO19: V 0.6W | BP19: cumm | BQ19: V 1.0E | BR19: cumm | BS19: V 0.7E | BT19: cumm
B20: L1 | C20: 0 | D20: 0 | E20: =C20+D20/12 -> 0 | F20: 0 | H20: 0 | I20: plf | J20: 0 | K20: 0 | L20: 0 | M20: 0 | Q20: L1 | R20: =$H$20 -> 0 | S20: =R20*0.6 -> 0 | T20: =$C$42/2*R20 -> 0 | U20: =T20*0.6 -> 0 | V20: 0 | W20: =V20*0.7 -> 0 | X20: =$C$42/2*V20 -> 0 | Y20: =X20*0.7 -> 0 | Z20: =$H$20 -> 0 | AA20: =Z20*0.6 -> 0 | AB20: =$D$42/2*Z20 -> 0 | AC20: =0.6*AB20 -> 0 | AD20: 0 | AE20: =AD20*0.7 -> 0 | AF20: =$D$42/2*AD20 -> 0 | AG20: =AF20*0.7 -> 0 | AH20: 0 | AI20: 0 | AJ20: =T20+AB20+AH20 -> 0 | AK20: =AK21+AJ20 -> 13166 | AL20: =AJ20*0.6 -> 0 | AM20: =AM21+AL20 -> 7899.6 | AN20: =X20+AF20+AI20 -> 0 | AO20: =AN20+AO21 -> 1302.1 | AP20: =AN20*0.7 -> 0 | AQ20: =AP20+AQ21 -> 911.47 | AT20: L1 | AU20: =$H$20 -> 0 | AV20: =AU20*0.6 -> 0 | AW20: =$I$42/2*AU20 -> 0 | AX20: =AW20*0.6 -> 0 | AY20: 0 | AZ20: =AY20*0.7 -> 0 | BA20: =$I$42/2*AY20 -> 0 | BB20: =BA20*0.7 -> 0 | BC20: =$H$20 -> 0 | BD20: =BC20*0.6 -> 0 | BE20: =$J$42/2*BC20 -> 0 | BF20: =0.6*BE20 -> 0 | BG20: 0 | BH20: =BG20*0.7 -> 0 | BI20: =$J$42/2*BG20 -> 0 | BJ20: =BI20*0.7 -> 0 | BK20: 0 | BL20: 0 | BM20: =AW20+BE20+BK20 -> 0 | BN20: =BN21+BM20 -> 12258 | BO20: =BM20*0.6 -> 0 | BP20: =BP21+BO20 -> 7354.8 | BQ20: =BA20+BI20+BL20 -> 0 | BR20: =BQ20+BR21 -> 1212.3 | BS20: =BQ20*0.7 -> 0 | BT20: =BS20+BT21 -> 848.61
B21: L2 | C21: 10 | D21: 8.25 | E21: =C21+D21/12 -> 10.6875 | F21: =IF(E21>0,E21-(C15+C14+2*1.5+IF(C13="single",1.5,3))/12-_xlfn.XLOOKUP(E21,E20,E20,,-1),0) -> 8.75 | H21: 236 | I21: plf | J21: 33.8 | K21: 65.6 | L21: 19.3 | M21: 119.6 | Q21: L2 | R21: =$H$21 -> 236 | S21: =R21*0.6 -> 141.6 | T21: =$C$42/2*R21 -> 0 | U21: =T21*0.6 -> 0 | V21: 33.8 | W21: =V21*0.7 -> 23.66 | X21: =$C$42/2*V21 -> 0 | Y21: =X21*0.7 -> 0 | Z21: =$H$21 -> 236 | AA21: =Z21*0.6 -> 141.6 | AB21: =$D$42/2*Z21 -> 3422 | AC21: =0.6*AB21 -> 2053.2 | AD21: 33.8 | AE21: =AD21*0.7 -> 23.66 | AF21: =$D$42/2*AD21 -> 490.1 | AG21: =AF21*0.7 -> 343.07 | AH21: 0 | AI21: 0 | AJ21: =T21+AB21+AH21 -> 3422 | AK21: =AK22+AJ21 -> 13166 | AL21: =AJ21*0.6 -> 2053.2 | AM21: =AM22+AL21 -> 7899.6 | AN21: =X21+AF21+AI21 -> 490.1 | AO21: =AN21+AO22 -> 1302.1 | AP21: =AN21*0.7 -> 343.07 | AQ21: =AP21+AQ22 -> 911.47 | AT21: L2 | AU21: =$H$21 -> 236 | AV21: =AU21*0.6 -> 141.6 | AW21: =$I$42/2*AU21 -> 0 | AX21: =AW21*0.6 -> 0 | AY21: 33.8 | AZ21: =AY21*0.7 -> 23.66 | BA21: =$I$42/2*AY21 -> 0 | BB21: =BA21*0.7 -> 0 | BC21: =$H$21 -> 236 | BD21: =BC21*0.6 -> 141.6 | BE21: =$J$42/2*BC21 -> 3186 | BF21: =0.6*BE21 -> 1911.6 | BG21: 33.8 | BH21: =BG21*0.7 -> 23.66 | BI21: =$J$42/2*BG21 -> 456.3 | BJ21: =BI21*0.7 -> 319.41 | BK21: 0 | BL21: 0 | BM21: =AW21+BE21+BK21 -> 3186 | BN21: =BN22+BM21 -> 12258 | BO21: =BM21*0.6 -> 1911.6 | BP21: =BP22+BO21 -> 7354.8 | BQ21: =BA21+BI21+BL21 -> 456.3 | BR21: =BQ21+BR22 -> 1212.3 | BS21: =BQ21*0.7 -> 319.41 | BT21: =BS21+BT22 -> 848.61
B22: L3 | C22: 21 | D22: 4.5 | E22: =C22+D22/12 -> 21.375 | F22: =IF(E22>0,E22-(C15+C14+2*1.5+IF(C13="single",1.5,3))/12-_xlfn.XLOOKUP(E22,E20:E21,E20:E21,,-1),0) -> 8.75 | H22: 229 | I22: plf | J22: 37.1 | K22: 71.8 | L22: 21.1 | M22: 131.1 | Q22: L3 | R22: =$H$22 -> 229 | S22: =R22*0.6 -> 137.4 | T22: =$C$42/2*R22 -> 0 | U22: =T22*0.6 -> 0 | V22: 37.1 | W22: =V22*0.7 -> 25.97 | X22: =$C$42/2*V22 -> 0 | Y22: =X22*0.7 -> 0 | Z22: =$H$22 -> 229 | AA22: =Z22*0.6 -> 137.4 | AB22: =$D$42/2*Z22 -> 3320.5 | AC22: =0.6*AB22 -> 1992.3 | AD22: 37.1 | AE22: =AD22*0.7 -> 25.97 | AF22: =$D$42/2*AD22 -> 537.95 | AG22: =AF22*0.7 -> 376.565 | AH22: 0 | AI22: 0 | AJ22: =T22+AB22+AH22 -> 3320.5 | AK22: =AK23+AJ22 -> 9744 | AL22: =AJ22*0.6 -> 1992.3 | AM22: =AM23+AL22 -> 5846.4 | AN22: =X22+AF22+AI22 -> 537.95 | AO22: =AN22+AO23 -> 812 | AP22: =AN22*0.7 -> 376.565 | AQ22: =AP22+AQ23 -> 568.4 | AT22: L3 | AU22: =$H$22 -> 229 | AV22: =AU22*0.6 -> 137.4 | AW22: =$I$42/2*AU22 -> 0 | AX22: =AW22*0.6 -> 0 | AY22: 37.1 | AZ22: =AY22*0.7 -> 25.97 | BA22: =$I$42/2*AY22 -> 0 | BB22: =BA22*0.7 -> 0 | BC22: =$H$22 -> 229 | BD22: =BC22*0.6 -> 137.4 | BE22: =$J$42/2*BC22 -> 3091.5 | BF22: =0.6*BE22 -> 1854.9 | BG22: 37.1 | BH22: =BG22*0.7 -> 25.97 | BI22: =$J$42/2*BG22 -> 500.85 | BJ22: =BI22*0.7 -> 350.595 | BK22: 0 | BL22: 0 | BM22: =AW22+BE22+BK22 -> 3091.5 | BN22: =BN23+BM22 -> 9072 | BO22: =BM22*0.6 -> 1854.9 | BP22: =BP23+BO22 -> 5443.2 | BQ22: =BA22+BI22+BL22 -> 500.85 | BR22: =BQ22+BR23 -> 756 | BS22: =BQ22*0.7 -> 350.595 | BT22: =BS22+BT23 -> 529.2
B23: L4 | C23: 0 | D23: 0 | E23: =C23+D23/12 -> 0 | F23: =IF(E23>0,E23-(C15+C14+2*1.5+IF(C13="single",1.5,3))/12-_xlfn.XLOOKUP(E23,E20:E22,E20:E22,,-1),0) -> 0 | H23: 0 | I23: plf | J23: 0 | K23: 0 | L23: 0 | M23: 0 | Q23: L4 | R23: =$H$23 -> 0 | S23: =R23*0.6 -> 0 | T23: =$C$42/2*R23 -> 0 | U23: =T23*0.6 -> 0 | V23: 0 | W23: =V23*0.7 -> 0 | X23: =$C$42/2*V23 -> 0 | Y23: =X23*0.7 -> 0 | Z23: =$H$23 -> 0 | AA23: =Z23*0.6 -> 0 | AB23: =$D$42/2*Z23 -> 0 | AC23: =0.6*AB23 -> 0 | AD23: 0 | AE23: =AD23*0.7 -> 0 | AF23: =$D$42/2*AD23 -> 0 | AG23: =AF23*0.7 -> 0 | AH23: 0 | AI23: 0 | AJ23: =T23+AB23+AH23 -> 0 | AK23: =AK24+AJ23 -> 6423.5 | AL23: =AJ23*0.6 -> 0 | AM23: =AM24+AL23 -> 3854.1 | AN23: =X23+AF23+AI23 -> 0 | AO23: =AN23+AO24 -> 274.05 | AP23: =AN23*0.7 -> 0 | AQ23: =AP23+AQ24 -> 191.835 | AT23: L4 | AU23: =$H$23 -> 0 | AV23: =AU23*0.6 -> 0 | AW23: =$I$42/2*AU23 -> 0 | AX23: =AW23*0.6 -> 0 | AY23: 0 | AZ23: =AY23*0.7 -> 0 | BA23: =$I$42/2*AY23 -> 0 | BB23: =BA23*0.7 -> 0 | BC23: =$H$23 -> 0 | BD23: =BC23*0.6 -> 0 | BE23: =$J$42/2*BC23 -> 0 | BF23: =0.6*BE23 -> 0 | BG23: 0 | BH23: =BG23*0.7 -> 0 | BI23: =$J$42/2*BG23 -> 0 | BJ23: =BI23*0.7 -> 0 | BK23: 0 | BL23: 0 | BM23: =AW23+BE23+BK23 -> 0 | BN23: =BN24+BM23 -> 5980.5 | BO23: =BM23*0.6 -> 0 | BP23: =BP24+BO23 -> 3588.3 | BQ23: =BA23+BI23+BL23 -> 0 | BR23: =BQ23+BR24 -> 255.15 | BS23: =BQ23*0.7 -> 0 | BT23: =BS23+BT24 -> 178.605
B24: L5 | C24: 0 | D24: 0 | E24: =C24+D24/12 -> 0 | F24: =IF(E24>0,E24-(C15+C14+2*1.5+IF(C13="single",1.5,3))/12-_xlfn.XLOOKUP(E24,E20:E23,E20:E23,,-1),0) -> 0 | H24: 0 | I24: plf | J24: 0 | K24: 0 | L24: 0 | M24: 0 | Q24: L5 | R24: =$H$24 -> 0 | S24: =R24*0.6 -> 0 | T24: =$C$42/2*R24 -> 0 | U24: =T24*0.6 -> 0 | V24: 0 | W24: =V24*0.7 -> 0 | X24: =$C$42/2*V24 -> 0 | Y24: =X24*0.7 -> 0 | Z24: =$H$24 -> 0 | AA24: =Z24*0.6 -> 0 | AB24: =$D$42/2*Z24 -> 0 | AC24: =0.6*AB24 -> 0 | AD24: 0 | AE24: =AD24*0.7 -> 0 | AF24: =$D$42/2*AD24 -> 0 | AG24: =AF24*0.7 -> 0 | AH24: 0 | AI24: 0 | AJ24: =T24+AB24+AH24 -> 0 | AK24: =AK25+IF(AJ24=0,0,AJ24) -> 6423.5 | AL24: =AJ24*0.6 -> 0 | AM24: =AM25+AL24 -> 3854.1 | AN24: =X24+AF24+AI24 -> 0 | AO24: =AN24+AO25 -> 274.05 | AP24: =AN24*0.7 -> 0 | AQ24: =AP24+AQ25 -> 191.835 | AT24: L5 | AU24: =$H$24 -> 0 | AV24: =AU24*0.6 -> 0 | AW24: =$I$42/2*AU24 -> 0 | AX24: =AW24*0.6 -> 0 | AY24: 0 | AZ24: =AY24*0.7 -> 0 | BA24: =$I$42/2*AY24 -> 0 | BB24: =BA24*0.7 -> 0 | BC24: =$H$24 -> 0 | BD24: =BC24*0.6 -> 0 | BE24: =$J$42/2*BC24 -> 0 | BF24: =0.6*BE24 -> 0 | BG24: 0 | BH24: =BG24*0.7 -> 0 | BI24: =$J$42/2*BG24 -> 0 | BJ24: =BI24*0.7 -> 0 | BK24: 0 | BL24: 0 | BM24: =AW24+BE24+BK24 -> 0 | BN24: =BN25+IF(BM24=0,0,BM24) -> 5980.5 | BO24: =BM24*0.6 -> 0 | BP24: =BP25+BO24 -> 3588.3 | BQ24: =BA24+BI24+BL24 -> 0 | BR24: =BQ24+BR25 -> 255.15 | BS24: =BQ24*0.7 -> 0 | BT24: =BS24+BT25 -> 178.605
B25: Roof | C25: =(33+32)/2 -> 32.5 | D25: =(10.5+5.625)/2 -> 8.0625 | E25: =C25+D25/12 -> 33.171875 | F25: =E25-(C17+C16+2*1.5+IF(C13="single",1.5,3))/12-_xlfn.XLOOKUP(E25,E20:E24,E20:E24,,-1) -> 8.6770833 | H25: 443 | I25: plf | J25: 18.9 | K25: 36.6 | L25: 10.8 | M25: 66.7 | Q25: Roof | R25: =$H$25 -> 443 | S25: =R25*0.6 -> 265.8 | T25: =$C$42/2*R25 -> 0 | U25: =T25*0.6 -> 0 | V25: 18.9 | W25: =V25*0.7 -> 13.23 | X25: =$C$42/2*V25 -> 0 | Y25: =X25*0.7 -> 0 | Z25: =$H$25 -> 443 | AA25: =Z25*0.6 -> 265.8 | AB25: =$D$42/2*Z25 -> 6423.5 | AC25: =0.6*AB25 -> 3854.1 | AD25: 18.9 | AE25: =AD25*0.7 -> 13.23 | AF25: =$D$42/2*AD25 -> 274.05 | AG25: =AF25*0.7 -> 191.835 | AH25: 0 | AI25: 0 | AJ25: =T25+AB25+AH25 -> 6423.5 | AK25: =AJ25 -> 6423.5 | AL25: =AJ25*0.6 -> 3854.1 | AM25: =AL25 -> 3854.1 | AN25: =X25+AF25+AI25 -> 274.05 | AO25: =AN25 -> 274.05 | AP25: =AN25*0.7 -> 191.835 | AQ25: =AP25 -> 191.835 | AT25: Roof | AU25: =$H$25 -> 443 | AV25: =AU25*0.6 -> 265.8 | AW25: =$I$42/2*AU25 -> 0 | AX25: =AW25*0.6 -> 0 | AY25: 18.9 | AZ25: =AY25*0.7 -> 13.23 | BA25: =$I$42/2*AY25 -> 0 | BB25: =BA25*0.7 -> 0 | BC25: =$H$25 -> 443 | BD25: =BC25*0.6 -> 265.8 | BE25: =$J$42/2*BC25 -> 5980.5 | BF25: =0.6*BE25 -> 3588.3 | BG25: 18.9 | BH25: =BG25*0.7 -> 13.23 | BI25: =$J$42/2*BG25 -> 255.15 | BJ25: =BI25*0.7 -> 178.605 | BK25: 0 | BL25: 0 | BM25: =AW25+BE25+BK25 -> 5980.5 | BN25: =BM25 -> 5980.5 | BO25: =BM25*0.6 -> 3588.3 | BP25: =BO25 -> 3588.3 | BQ25: =BA25+BI25+BL25 -> 255.15 | BR25: =BQ25 -> 255.15 | BS25: =BQ25*0.7 -> 178.605 | BT25: =BS25 -> 178.605
B26: W Uplift | H26: -22.9 | I26: psf | R26: =$H$26 -> -22.9 | S26: =R26*0.6 -> -13.74 | T26: =$I$42/2*R26 -> 0 | U26: =T26*0.6 -> 0 | Z26: =$H$26 -> -22.9 | AA26: =Z26*0.6 -> -13.74 | AB26: =$J$42/2*Z26 -> -309.15 | AC26: =0.6*AB26 -> -185.49 | AU26: =$H$26 -> -22.9 | AV26: =AU26*0.6 -> -13.74 | AW26: =$I$42/2*AU26 -> 0 | AX26: =AW26*0.6 -> 0 | BC26: =$H$26 -> -22.9 | BD26: =BC26*0.6 -> -13.74 | BE26: =$J$42/2*BC26 -> -309.15 | BF26: =0.6*BE26 -> -185.49
B27: E Uplift | C27: Sds | D27: 0.18 | H27: =0.2*D27 -> 0.036 | I27: xD psf
Y28: user override stud height if required each level | BB28: user override stud height if required each level
B29: DL | Q29: Wall | R29: Length | S29: Flr Spac | T29: Flr Trib | U29: Rf Space | V29: Rf Trib | W29: Wall | X29: Parapet | Y29: L2 | Z29: L3 | AA29: L4 | AB29: L5 | AC29: LR | AD29: V % | AT29: Wall | AU29: Length | AV29: Flr Spac | AW29: Flr Trib | AX29: Rf Space | AY29: Rf Trib | AZ29: Wall | BA29: Parapet | BB29: L2 | BC29: L3 | BD29: L4 | BE29: L5 | BF29: LR | BG29: V %
B30: Roof | C30: 20 | D30: 100% of Min Roof Dead Load | Q30: =R16&".01" -> A.01 | R30: 29 | S30: 12 | T30: =S30/2 -> 6 | U30: 4 | V30: =U30/2 -> 2 | W30: Wall 3 | X30: 6 | AD30: =R30/R46 -> 1 | AT30: =AU$16&".01" -> 1.01 | AU30: 29 | AV30: 12 | AW30: =AV30/2 -> 6 | AX30: 4 | AY30: =AX30/2 -> 2 | AZ30: Wall 3 | BA30: 6 | BG30: =AU30/AU46 -> 1
C31: =0.9*C30 -> 18 | D31: 90% of Min Roof Dead Load | Q31: =R16&".02" -> A.02 | T31: =S31/2 -> 0 | V31: =U31/2 -> 0 | AT31: =AU$16&".02" -> 1.02 | AW31: =AV31/2 -> 0 | AY31: =AX31/2 -> 0
B32: Floor | C32: 26 | D32: Min Floor Dead Load | Q32: =R16&".03" -> A.03 | T32: =S32/2 -> 0 | V32: =U32/2 -> 0 | AT32: =AU$16&".03" -> 1.03 | AW32: =AV32/2 -> 0 | AY32: =AX32/2 -> 0
B33: Wall 1 | C33: 11 | D33: Single Interior 2x4 Wall | Q33: =R16&".04" -> A.04 | T33: =S33/2 -> 0 | V33: =U33/2 -> 0 | AT33: =AU$16&".04" -> 1.04 | AW33: =AV33/2 -> 0 | AY33: =AX33/2 -> 0
B34: Wall 2 | C34: 13 | D34: Double Interior 2x4 Wall | Q34: =R16&".05" -> A.05 | T34: =S34/2 -> 0 | V34: =U34/2 -> 0 | AT34: =AU$16&".05" -> 1.05 | AW34: =AV34/2 -> 0 | AY34: =AX34/2 -> 0
B35: Wall 3 | C35: 18 | D35: Single Exterior 2x6 Wall | Q35: =R16&".06" -> A.06 | T35: =S35/2 -> 0 | V35: =U35/2 -> 0 | AT35: =AU$16&".06" -> 1.06 | AW35: =AV35/2 -> 0 | AY35: =AX35/2 -> 0
B36: Wall 4 | Q36: =R16&".07" -> A.07 | T36: =S36/2 -> 0 | V36: =U36/2 -> 0 | AT36: =AU$16&".07" -> 1.07 | AW36: =AV36/2 -> 0 | AY36: =AX36/2 -> 0
B37: Wall 5 | Q37: =R16&".08" -> A.08 | T37: =S37/2 -> 0 | V37: =U37/2 -> 0 | AT37: =AU$16&".08" -> 1.08 | AW37: =AV37/2 -> 0 | AY37: =AX37/2 -> 0
B38: Wall 6 | Q38: =R16&".09" -> A.09 | T38: =S38/2 -> 0 | V38: =U38/2 -> 0 | AT38: =AU$16&".09" -> 1.09 | AW38: =AV38/2 -> 0 | AY38: =AX38/2 -> 0
Q39: =R16&".10" -> A.10 | T39: =S39/2 -> 0 | V39: =U39/2 -> 0 | AT39: =AU$16&".10" -> 1.10 | AW39: =AV39/2 -> 0 | AY39: =AX39/2 -> 0
C40: line to line spacing | I40: line to line spacing | Q40: =R16&".11" -> A.11 | T40: =S40/2 -> 0 | V40: =U40/2 -> 0 | AT40: =AU$16&".11" -> 1.11 | AW40: =AV40/2 -> 0 | AY40: =AX40/2 -> 0
B41: NS Lines | C41: left ft | D41: right ft | E41: total ft | H41: EW Lines | I41: left ft | J41: right ft | K41: total ft | Q41: =R16&".12" -> A.12 | T41: =S41/2 -> 0 | V41: =U41/2 -> 0 | AT41: =AU$16&".12" -> 1.12 | AW41: =AV41/2 -> 0 | AY41: =AX41/2 -> 0
B42: A | C42: 0 | D42: 29 | E42: =C42+D42 -> 29 | H42: 1 | I42: 0 | J42: 27 | K42: =I42+J42 -> 27 | Q42: =R16&".13" -> A.13 | T42: =S42/2 -> 0 | V42: =U42/2 -> 0 | AT42: =AU$16&".13" -> 1.13 | AW42: =AV42/2 -> 0 | AY42: =AX42/2 -> 0
B43: B | C43: 29 | D43: 6 | E43: =C43+D43 -> 35 | H43: 2 | I43: 27 | J43: 14 | K43: =I43+J43 -> 41 | Q43: =R16&".14" -> A.14 | T43: =S43/2 -> 0 | V43: =U43/2 -> 0 | AT43: =AU$16&".14" -> 1.14 | AW43: =AV43/2 -> 0 | AY43: =AX43/2 -> 0
B44: C | C44: 6 | D44: 29 | E44: =C44+D44 -> 35 | H44: 3 | I44: 14 | J44: 13 | K44: =I44+J44 -> 27 | Q44: =R16&".15" -> A.15 | T44: =S44/2 -> 0 | V44: =U44/2 -> 0 | AT44: =AU$16&".15" -> 1.15 | AW44: =AV44/2 -> 0 | AY44: =AX44/2 -> 0
...

Sheet Sheet3
B2: Fire Rated Assembly
B4: Name | C4: Use Limit | D4: Stud Req'd | E4: Max Stud Spacing [in o.c.] | F4: Sheathing Limit | G4: Limit "m" 78%F'c for Le/d >= 33
B5: None
B6: IBC Table 721.2(2) 12-1.1 | C6: Interior | D6: 2x4 | E6: 16 | G6: 0.78
B7: IBC Table 721.2(2) 12-1.2 | C7: Interior | D7: 2x4 | E7: 16 | G7: 1
B8: IBC Table 721.2(2) 12-1.3 | C8: Interior | D8: 2x4 | E8: 16 | G8: 1
B9: IBC Table 721.2(2) 12-1.4 | C9: Interior | D9: 2x4 | E9: 16 | G9: 1
B10: IBC Table 721.2(2) 14-1.1 | C10: Interior | D10: 2x4 | E10: 16 | G10: 0.78
B11: IBC Table 721.2(2) 14-1.2 | C11: Interior | D11: 2x4 | E11: 16 | G11: 0.78
B12: IBC Table 721.2(2) 14-1.3 | C12: Interior | D12: 2x4 | E12: 16 | G12: 0.78
B13: IBC Table 721.2(2) 14-1.4 | C13: Interior | D13: 2x4 | E13: 16
B14: IBC Table 721.2(2) 14-1.5 | C14: Interior | D14: 2x4 | E14: 16 | G14: 0.78
B15: IBC Table 721.2(2) 15-1.1 | C15: Int / Ext | D15: 2x4 | E15: 16 | G15: 0.78
B16: IBC Table 721.2(2) 15-1.2 | C16: Int / Ext | D16: 2x4 | E16: 16 | G16: 0.78
B17: IBC Table 721.2(2) 15-1.3 | C17: Int / Ext | D17: 2x4 | E17: 16 | G17: 0.78
B18: IBC Table 721.2(2) 15-1.5 | C18: Int / Ext | D18: 2x4 | E18: 16 | F18: Yes | G18: 0.78
B19: IBC Table 721.2(2) 15-1.6 | C19: Int / Ext | D19: 2x6 | E19: 16 | G19: 0.78
B20: IBC Table 721.2(2) 15-1.7 | C20: Int / Ext | D20: 2x6 | E20: 16 | G20: 0.78
B21: IBC Table 721.2(2) 15-1.8 | C21: Int / Ext | D21: 2x6 | E21: 16 | G21: 0.78
B22: IBC Table 721.2(2) 15-1.12 | C22: Int / Ext | D22: 2x6 | E22: 16 | F22: Yes | G22: 1
B23: IBC Table 721.2(2) 15-1.13 | C23: Int / Ext | D23: 2x6 | E23: 16 | F23: Yes | G23: 1
B24: IBC Table 721.2(2) 15-1.14 | C24: Int / Ext | D24: 2x6 | E24: 16 | F24: Yes | G24: 1
B25: IBC Table 721.2(2) 15-1.15 | C25: Int / Ext | D25: 2x4 | E25: 16 | F25: Yes | G25: 1
B26: IBC Table 721.2(2) 15-1.16 | C26: Int / Ext | D26: 2x6 | E26: 24 | F26: Yes | G26: 1
B27: IBC Table 721.2(2) 16-1.1 | C27: Exterior | D27: 2x4 | E27: 16 | F27: Yes | G27: 1
B28: IBC Table 721.2(2) 16-1.2 | C28: Exterior | D28: 2x6 | E28: 16 | F28: Yes | G28: 1
B29: IBC Table 721.2(2) 16-1.3 | C29: Exterior | D29: 2x6 | E29: 16 | F29: Yes | G29: 1
B30: IBC Table 721.2(2) 16-1.4 | C30: Exterior | D30: 2x6 | E30: 24 | F30: Yes | G30: 1
B31: UL

Sheet Lateral
B2: LATERAL DESIGN:
O3: Holdown Schedule (Simpson 2024-2025) | S3: DFL #2 | U3: Diaphragm Sheathing Schedule (SDPWS 2021)
C4: 1.0 W | D4: 1.0E | F4: 1.0 E | O4: HD Mark | P4: Holdown | Q4: Cap ASD | R4: 2x4 Post | S4: 2x6 Post | U4: Level | V4: C1E ASD | W4: C1W ASD | X4: C3E ASD | Y4: C3W ASD
B5: w dia (EW1) | C5: 210 | D5: 578 | F5: D roof | G5: 26 | H5: psf | I5: L roof-ns | J5: 146 | K5: ft | L5: Cs | M5: 0.03 | O5: A | P5: LSTHD8 | Q5: {=IFERROR(INDEX(hdt_dfsp,MATCH(P5,holdown,0),0),"")} -> 1395 | R5: {=IFERROR(INDEX(post24,MATCH(P5,holdown,0),0),"")} -> 2-2x4 | S5: {=IFERROR(INDEX(post26,MATCH(P5,holdown,0),0),"")} -> 2-2x6 | U5: Roof | V5: =[1]Diaphragm!G5 -> 255 | W5: =[1]Diaphragm!I5 -> 357 | X5: =[1]Diaphragm!K5 -> 189 | Y5: =[1]Diaphragm!M5 -> 265
B6: w dia (NS1) | C6: 210 | D6: 363 | F6: D wall | G6: 20 | H6: psf | I6: L roof-ew | J6: 90 | K6: ft | O6: B | P6: STHD14 | Q6: {=IFERROR(INDEX(hdt_dfsp,MATCH(P6,holdown,0),0),"")} -> 3065 | R6: {=IFERROR(INDEX(post24,MATCH(P6,holdown,0),0),"")} -> 2-2x4 | S6: {=IFERROR(INDEX(post26,MATCH(P6,holdown,0),0),"")} -> 2-2x6
B7: w dia3 | F7: Dpartition | G7: 10 | H7: psf | I7: h wall+para | J7: 16 | K7: ft | O7: C | P7: HDU4-SDS2.5 | Q7: {=IFERROR(INDEX(hdt_dfsp,MATCH(P7,holdown,0),0),"")} | R7: {=IFERROR(INDEX(post24,MATCH(P7,holdown,0),0),"")} | S7: {=IFERROR(INDEX(post26,MATCH(P7,holdown,0),0),"")}
B8: w dia4 | F8: V | G8: 14344 | H8: lb (Cs W) | O8: D | Q8: {=IFERROR(INDEX(hdt_dfsp,MATCH(P8,holdown,0),0),"")} | R8: {=IFERROR(INDEX(post24,MATCH(P8,holdown,0),0),"")} | S8: {=IFERROR(INDEX(post26,MATCH(P8,holdown,0),0),"")}
O9: E | Q9: {=IFERROR(INDEX(hdt_dfsp,MATCH(P9,holdown,0),0),"")} | R9: {=IFERROR(INDEX(post24,MATCH(P9,holdown,0),0),"")} | S9: {=IFERROR(INDEX(post26,MATCH(P9,holdown,0),0),"")}
B10: Lines | G10: Trib | H10: Wind | I10: # | J10: Seismic | K10: # | L10: =IF(AND(I12>K12,I13>K13,I14>K14,I15>K15),"WIND GOVERNS",IF(AND(I12<K12,I13<K13,I14<K14,I15<K15),"SEISMIC GOVERNS","CHECK WIND AND SEISMIC")) -> SEISMIC GOVERNS | O10: F | Q10: {=IFERROR(INDEX(hdt_dfsp,MATCH(P10,holdown,0),0),"")} | R10: {=IFERROR(INDEX(post24,MATCH(P10,holdown,0),0),"")} | S10: {=IFERROR(INDEX(post26,MATCH(P10,holdown,0),0),"")}
D11: =TEXT(B11,0)&" to "&TEXT(B12,0) -> 0 to EW-WL1 | E11: 0 | F11: ft | G11: ft | H11: 1 | I11: 0.6 | J11: 1 | K11: 0.7
B12: EW-WL1 | D12: =TEXT(B12,0)&" to "&TEXT(B13,0) -> EW-WL1 to EW-WL2 | E12: 28 | F12: ft | G12: =E11+E12/2 -> 14 | H12: =G12*$C$5 -> 2940 | I12: =ROUNDUP(H12*0.6,0) -> 1764 | J12: =G12*$D$5 -> 8092 | K12: =J12*0.7 -> 5664.4 | O12: Shearwall Sheathing Schedule (SDPWS 2021)
B13: EW-WL2 | D13: =TEXT(B13,0)&" to "&TEXT(B14,0) -> EW-WL2 to EW-WL3 | E13: 32 | F13: ft | G13: =E12/2+E13/2 -> 30 | H13: =G13*$C$5 -> 6300 | I13: =ROUNDUP(H13*0.6,0) -> 3780 | J13: =G13*$D$5 -> 17340 | K13: =J13*0.7 -> 12138 | O13: SW Mark | P13: Cap ASD W | Q13: Cap ASD E | R13: Sheathing
B14: EW-WL3 | D14: =TEXT(B14,0)&" to "&TEXT(B15,0) -> EW-WL3 to EW-WL4 | E14: 22 | F14: ft | G14: =E13/2+E14/2 -> 27 | H14: =G14*$C$5 -> 5670 | I14: =ROUNDUP(H14*0.6,0) -> 3402 | J14: =G14*$D$5 -> 15606 | K14: =J14*0.7 -> 10924.2 | O14: 1 | P14: {=IFERROR(INDEX(sw2.0,MATCH(R14,sheathing,0),0),"")} | Q14: {=IFERROR(INDEX(sw2.8,MATCH(R14,sheathing,0),0),"")} | R14: DOUBLE 1/2" Gypsum Wallboard with No. 6 Type S or W drywall screws 1-1/4" long at 4"oc edge and 16"oc field
B15: EW-WL4 | D15: =TEXT(B15,0)&" to "&TEXT(B16,0) -> EW-WL4 to 0 | E15: 0 | F15: ft | G15: =E14/2+E15 -> 11 | H15: =G15*$C$5 -> 2310 | I15: =ROUNDUP(H15*0.6,0) -> 1386 | J15: =G15*$D$5 -> 6358 | K15: =J15*0.7 -> 4450.6 | O15: 2 | P15: {=IFERROR(INDEX(sw2.0,MATCH(R15,sheathing,0),0),"")} | Q15: {=IFERROR(INDEX(sw2.8,MATCH(R15,sheathing,0),0),"")} | R15: 3/8" Blocked Wood Structural Panel Sheathing with 8d at 6"oc edge and 12"oc field
O16: 3 | P16: {=IFERROR(INDEX(sw2.0,MATCH(R16,sheathing,0),0),"")} | Q16: {=IFERROR(INDEX(sw2.8,MATCH(R16,sheathing,0),0),"")} | R16: 3/8" Blocked Wood Structural Panel Sheathing with 8d at 4"oc edge and 12"oc field
L17: =IF(AND(I19>K19,I20>K20,I21>K21,I22>K22,I23>K23,I24>K24,I25>K25,I26>K26),"WIND GOVERNS",IF(AND(I19<K19,I20<K20,I21<K21,I22<K22,I23<K23,I24<K24,I25<K25,I26<K26),"SEISMIC GOVERNS","CHECK WIND AND SEISMIC")) -> SEISMIC GOVERNS | O17: 4 | P17: {=IFERROR(INDEX(sw2.0,MATCH(R17,sheathing,0),0),"")} | Q17: {=IFERROR(INDEX(sw2.8,MATCH(R17,sheathing,0),0),"")}
D18: =TEXT(B18,0)&" to "&TEXT(B19,0) -> 0 to NS-WL1 | E18: 0 | F18: ft | O18: 5 | P18: {=IFERROR(INDEX(sw2.0,MATCH(R18,sheathing,0),0),"")} | Q18: {=IFERROR(INDEX(sw2.8,MATCH(R18,sheathing,0),0),"")}
B19: NS-WL1 | D19: =TEXT(B19,0)&" to "&TEXT(B20,0) -> NS-WL1 to NS-WL2 | E19: 22 | F19: ft | G19: =E18+E19/2 -> 11 | H19: =G19*$C$6 -> 2310 | I19: =ROUNDUP(H19*0.6,0) -> 1386 | J19: =G19*$D$6 -> 3993 | K19: =J19*0.7 -> 2795.1 | O19: 6 | P19: {=IFERROR(INDEX(sw2.0,MATCH(R19,sheathing,0),0),"")} | Q19: {=IFERROR(INDEX(sw2.8,MATCH(R19,sheathing,0),0),"")}
B20: NS-WL2 | D20: =TEXT(B20,0)&" to "&TEXT(B21,0) -> NS-WL2 to NS-WL3 | E20: 23 | F20: ft | G20: =E19/2+E20/2 -> 22.5 | H20: =G20*$C$6 -> 4725 | I20: =ROUNDUP(H20*0.6,0) -> 2835 | J20: =G20*$D$6 -> 8167.5 | K20: =J20*0.7 -> 5717.25
B21: NS-WL3 | D21: =TEXT(B21,0)&" to "&TEXT(B22,0) -> NS-WL3 to NS-WL4 | E21: 16 | F21: ft | G21: =E20/2+E21/2 -> 19.5 | H21: =G21*$C$6 -> 4095 | I21: =ROUNDUP(H21*0.6,0) -> 2457 | J21: =G21*$D$6 -> 7078.5 | K21: =J21*0.7 -> 4954.95
B22: NS-WL4 | D22: =TEXT(B22,0)&" to "&TEXT(B23,0) -> NS-WL4 to NS-WL5 | E22: 12 | F22: ft | G22: =E21/2+E22/2 -> 14 | H22: =G22*$C$6 -> 2940 | I22: =ROUNDUP(H22*0.6,0) -> 1764 | J22: =G22*$D$6 -> 5082 | K22: =J22*0.7 -> 3557.4
B23: NS-WL5 | D23: =TEXT(B23,0)&" to "&TEXT(B24,0) -> NS-WL5 to NS-WL6 | E23: 46 | F23: ft | G23: =E22/2+E23/2 -> 29 | H23: =G23*$C$6 -> 6090 | I23: =ROUNDUP(H23*0.6,0) -> 3654 | J23: =G23*$D$6 -> 10527 | K23: =J23*0.7 -> 7368.9
B24: NS-WL6 | D24: =TEXT(B24,0)&" to "&TEXT(B25,0) -> NS-WL6 to NS-WL7 | E24: 23 | F24: ft | G24: =E23/2+E24/2 -> 34.5 | H24: =G24*$C$6 -> 7245 | I24: =ROUNDUP(H24*0.6,0) -> 4347 | J24: =G24*$D$6 -> 12523.5 | K24: =J24*0.7 -> 8766.45
B25: NS-WL7 | D25: =TEXT(B25,0)&" to "&TEXT(B26,0) -> NS-WL7 to NS-WL8 | E25: 23 | F25: ft | G25: =E24/2+E25/2 -> 23 | H25: =G25*$C$6 -> 4830 | I25: =ROUNDUP(H25*0.6,0) -> 2898 | J25: =G25*$D$6 -> 8349 | K25: =J25*0.7 -> 5844.3
B26: NS-WL8 | D26: =TEXT(B26,0)&" to "&TEXT(B27,0) -> NS-WL8 to 0 | E26: 0 | F26: ft | G26: =E25/2+E26 -> 11.5 | H26: =G26*$C$6 -> 2415 | I26: =ROUNDUP(H26*0.6,0) -> 1449 | J26: =G26*$D$6 -> 4174.5 | K26: =J26*0.7 -> 2922.15
B29: Shear Wall | F29: 0.6D | H29: 1.0W | I29: 0.6W | J29: 0.6W | K29: 0.6D+0.6W | L29: Wind | M29: ASD | N29: 0.6W | P29: 1.0E | Q29: 0.7E | R29: 0.7E | S29: 0.6D+0.7E | T29: Seismic | U29: ASD | V29: 0.7E | X29: Sheathing
B30: Mark | C30: Quanity | D30: L ft | E30: h ft | F30: Mr #-ft | H30: V # | I30: V # | J30: Mot #-ft | K30: Mnet | L30: Thd # | M30: HD Mark | N30: v plf | O30: SW Mark | P30: V # | Q30: V # | R30: Mot #-ft | S30: Mnet | T30: Thd # | U30: Mark | V30: v plf | W30: Mark | X30: Case
B31: EW-WL1.1 | C31: 1 | D31: 5.5 | E31: 12 | F31: =0.6*$G$6*E31*D31*D31/2 -> 2178 | H31: {=$H$12*D31/SUM($C$31:$C$33*$D$31:$D$33)} -> 445.04587 | I31: =H31*0.6 -> 267.02752 | J31: =I31*E31 -> 3204.3303 | K31: =IF(J31-F31>0,J31-F31,"none") -> 1026.3303 | L31: =IFERROR(ROUNDUP(K31/(D31-0.5),0),"") -> 206 | M31: =(IF(L31<$Q$5,$O$5,IF(L31<$Q$6,$O$6,IF(L31<$Q$7,$O$7,IF(L31<$Q$8,$O$8,IF(L31<$Q$9,$O$9,IF(L31<$Q$10,$O$10,""))))))) -> A | N31: =I31/D31 -> 48.550459 | O31: =(IF(N31<$P$14,$O$14,IF(N31<$P$15,$O$15,IF(N31<$P$16,$O$16,IF(N31<$P$17,$O$17,IF(N31<$P$18,$O$18,IF(N31<$P$19,$O$19,""))))))) -> 1 | P31: {=$J$12*D31/SUM($C$31:$C$33*$D$31:$D$33)} -> 1224.9358 | Q31: =P31*0.7 -> 857.45505 | R31: =Q31*E31 -> 10289.461 | S31: =IF(R31-F31>0,R31-F31,"none") -> 8111.4606 | T31: =IFERROR(ROUNDUP(S31/(D31-0.5),0),"") -> 1623 | U31: =(IF(T31<$Q$5,$O$5,IF(T31<$Q$6,$O$6,IF(T31<$Q$7,$O$7,IF(T31<$Q$8,$O$8,IF(T31<$Q$9,$O$9,IF(T31<$Q$10,$O$10,""))))))) -> B | V31: =Q31/D31 -> 155.90092 | W31: =(IF(V31<$Q$14,$O$14,IF(V31<$Q$15,$O$15,IF(V31<$Q$16,$O$16,IF(V31<$Q$17,$O$17,IF(V31<$Q$18,$O$18,IF(V31<$Q$19,$O$19,""))))))) -> 1 | X31: 3 | Y31: =IF(AND(X31=1,N31>$W$5),"drag",IF(AND(X31=3,N31>$Y$5),"drag",IF(AND(X31=1,V31>$V$5),"drag",IF(AND(X31=3,V31>$X$5),"drag",""))))
B32: EW-WL1.2 | C32: 1 | D32: =3+10/12 -> 3.8333333 | E32: 12 | F32: =0.6*$G$6*E32*D32*D32/2 -> 1058 | H32: {=$H$12*D32/SUM($C$31:$C$33*$D$31:$D$33)} -> 310.18349 | I32: =H32*0.6 -> 186.11009 | J32: =I32*E32 -> 2233.3211 | K32: =IF(J32-F32>0,J32-F32,"none") -> 1175.3211 | L32: =IFERROR(ROUNDUP(K32/(D32-0.5),0),"") -> 353 | M32: =(IF(L32<$Q$5,$O$5,IF(L32<$Q$6,$O$6,IF(L32<$Q$7,$O$7,IF(L32<$Q$8,$O$8,IF(L32<$Q$9,$O$9,IF(L32<$Q$10,$O$10,""))))))) -> A | N32: =I32/D32 -> 48.550459 | O32: =(IF(N32<$P$14,$O$14,IF(N32<$P$15,$O$15,IF(N32<$P$16,$O$16,IF(N32<$P$17,$O$17,IF(N32<$P$18,$O$18,IF(N32<$P$19,$O$19,""))))))) -> 1 | P32: {=$J$12*D32/SUM($C$31:$C$33*$D$31:$D$33)} -> 853.74312 | Q32: =P32*0.7 -> 597.62018 | R32: =Q32*E32 -> 7171.4422 | S32: =IF(R32-F32>0,R32-F32,"none") -> 6113.4422 | T32: =IFERROR(ROUNDUP(S32/(D32-0.5),0),"") -> 1835 | U32: =(IF(T32<$Q$5,$O$5,IF(T32<$Q$6,$O$6,IF(T32<$Q$7,$O$7,IF(T32<$Q$8,$O$8,IF(T32<$Q$9,$O$9,IF(T32<$Q$10,$O$10,""))))))) -> B | V32: =Q32/D32 -> 155.90092 | W32: =(IF(V32<$Q$14,$O$14,IF(V32<$Q$15,$O$15,IF(V32<$Q$16,$O$16,IF(V32<$Q$17,$O$17,IF(V32<$Q$18,$O$18,IF(V32<$Q$19,$O$19,""))))))) -> 1 | X32: 3 | Y32: =IF(AND(X32=1,N32>$W$5),"drag",IF(AND(X32=3,N32>$Y$5),"drag",IF(AND(X32=1,V32>$V$5),"drag",IF(AND(X32=3,V32>$X$5),"drag",""))))
B33: EW-WL1.3 | C33: 1 | D33: 27 | E33: 12 | F33: =0.6*$G$6*E33*D33*D33/2 -> 52488 | H33: {=$H$12*D33/SUM($C$31:$C$33*$D$31:$D$33)} -> 2184.7706 | I33: =H33*0.6 -> 1310.8624 | J33: =I33*E33 -> 15730.349 | K33: =IF(J33-F33>0,J33-F33,"none") -> none | L33: =IFERROR(ROUNDUP(K33/(D33-0.5),0),"") | M33: =(IF(L33<$Q$5,$O$5,IF(L33<$Q$6,$O$6,IF(L33<$Q$7,$O$7,IF(L33<$Q$8,$O$8,IF(L33<$Q$9,$O$9,IF(L33<$Q$10,$O$10,""))))))) | N33: =I33/D33 -> 48.550459 | O33: =(IF(N33<$P$14,$O$14,IF(N33<$P$15,$O$15,IF(N33<$P$16,$O$16,IF(N33<$P$17,$O$17,IF(N33<$P$18,$O$18,IF(N33<$P$19,$O$19,""))))))) -> 1 | P33: {=$J$12*D33/SUM($C$31:$C$33*$D$31:$D$33)} -> 6013.3211 | Q33: =P33*0.7 -> 4209.3248 | R33: =Q33*E33 -> 50511.897 | S33: =IF(R33-F33>0,R33-F33,"none") -> none | T33: =IFERROR(ROUNDUP(S33/(D33-0.5),0),"") | U33: =(IF(T33<$Q$5,$O$5,IF(T33<$Q$6,$O$6,IF(T33<$Q$7,$O$7,IF(T33<$Q$8,$O$8,IF(T33<$Q$9,$O$9,IF(T33<$Q$10,$O$10,""))))))) | V33: =Q33/D33 -> 155.90092 | W33: =(IF(V33<$Q$14,$O$14,IF(V33<$Q$15,$O$15,IF(V33<$Q$16,$O$16,IF(V33<$Q$17,$O$17,IF(V33<$Q$18,$O$18,IF(V33<$Q$19,$O$19,""))))))) -> 1 | X33: 3 | Y33: =IF(AND(X33=1,N33>$W$5),"drag",IF(AND(X33=3,N33>$Y$5),"drag",IF(AND(X33=1,V33>$V$5),"drag",IF(AND(X33=3,V33>$X$5),"drag",""))))
B34: EW-WL2.1 | C34: 1 | D34: 19.5 | E34: 12 | F34: =0.6*$G$6*E34*D34*D34/2 -> 27378 | H34: {=$H$13*D34/SUM($C$34:$C$37*$D$34:$D$37)} -> 2013.9344 | I34: =H34*0.6 -> 1208.3607 | J34: =I34*E34 -> 14500.328 | K34: =IF(J34-F34>0,J34-F34,"none") -> none | L34: =IFERROR(ROUNDUP(K34/(D34-0.5),0),"") | M34: =(IF(L34<$Q$5,$O$5,IF(L34<$Q$6,$O$6,IF(L34<$Q$7,$O$7,IF(L34<$Q$8,$O$8,IF(L34<$Q$9,$O$9,IF(L34<$Q$10,$O$10,""))))))) | N34: =I34/D34 -> 61.967213 | O34: =(IF(N34<$P$14,$O$14,IF(N34<$P$15,$O$15,IF(N34<$P$16,$O$16,IF(N34<$P$17,$O$17,IF(N34<$P$18,$O$18,IF(N34<$P$19,$O$19,""))))))) -> 1 | P34: {=$J$13*D34/SUM($C$34:$C$37*$D$34:$D$37)} -> 5543.1148 | Q34: =P34*0.7 -> 3880.1803 | R34: =Q34*E34 -> 46562.164 | S34: =IF(R34-F34>0,R34-F34,"none") -> 19184.164 | T34: =IFERROR(ROUNDUP(S34/(D34-0.5),0),"") -> 1010 | U34: =(IF(T34<$Q$5,$O$5,IF(T34<$Q$6,$O$6,IF(T34<$Q$7,$O$7,IF(T34<$Q$8,$O$8,IF(T34<$Q$9,$O$9,IF(T34<$Q$10,$O$10,""))))))) -> A | V34: =Q34/D34 -> 198.98361 | W34: =(IF(V34<$Q$14,$O$14,IF(V34<$Q$15,$O$15,IF(V34<$Q$16,$O$16,IF(V34<$Q$17,$O$17,IF(V34<$Q$18,$O$18,IF(V34<$Q$19,$O$19,""))))))) -> 1 | X34: 3 | Y34: =IF(AND(X34=1,N34>$W$5),"drag",IF(AND(X34=3,N34>$Y$5),"drag",IF(AND(X34=1,V34>$V$5),"drag",IF(AND(X34=3,V34>$X$5),"drag","")))) -> drag
B35: EW-WL2.2 | C35: 1 | D35: 8 | E35: 16 | F35: =0.6*$G$6*E35*D35*D35/2 -> 6144 | H35: {=$H$13*D35/SUM($C$34:$C$37*$D$34:$D$37)} -> 826.22951 | I35: =H35*0.6 -> 495.7377 | J35: =I35*E35 -> 7931.8033 | K35: =IF(J35-F35>0,J35-F35,"none") -> 1787.8033 | L35: =IFERROR(ROUNDUP(K35/(D35-0.5),0),"") -> 239 | M35: =(IF(L35<$Q$5,$O$5,IF(L35<$Q$6,$O$6,IF(L35<$Q$7,$O$7,IF(L35<$Q$8,$O$8,IF(L35<$Q$9,$O$9,IF(L35<$Q$10,$O$10,""))))))) -> A | N35: =I35/D35 -> 61.967213 | O35: =(IF(N35<$P$14,$O$14,IF(N35<$P$15,$O$15,IF(N35<$P$16,$O$16,IF(N35<$P$17,$O$17,IF(N35<$P$18,$O$18,IF(N35<$P$19,$O$19,""))))))) -> 1 | P35: {=$J$13*D35/SUM($C$34:$C$37*$D$34:$D$37)} -> 2274.0984 | Q35: =P35*0.7 -> 1591.8689 | R35: =Q35*E35 -> 25469.902 | S35: =IF(R35-F35>0,R35-F35,"none") -> 19325.902 | T35: =IFERROR(ROUNDUP(S35/(D35-0.5),0),"") -> 2577 | U35: =(IF(T35<$Q$5,$O$5,IF(T35<$Q$6,$O$6,IF(T35<$Q$7,$O$7,IF(T35<$Q$8,$O$8,IF(T35<$Q$9,$O$9,IF(T35<$Q$10,$O$10,""))))))) -> B | V35: =Q35/D35 -> 198.98361 | W35: =(IF(V35<$Q$14,$O$14,IF(V35<$Q$15,$O$15,IF(V35<$Q$16,$O$16,IF(V35<$Q$17,$O$17,IF(V35<$Q$18,$O$18,IF(V35<$Q$19,$O$19,""))))))) -> 1 | X35: 3 | Y35: =IF(AND(X35=1,N35>$W$5),"drag",IF(AND(X35=3,N35>$Y$5),"drag",IF(AND(X35=1,V35>$V$5),"drag",IF(AND(X35=3,V35>$X$5),"drag","")))) -> drag
B36: EW-WL2.3 | C36: 1 | D36: 17 | E36: 12 | F36: =0.6*$G$6*E36*D36*D36/2 -> 20808 | H36: {=$H$13*D36/SUM($C$34:$C$37*$D$34:$D$37)} -> 1755.7377 | I36: =H36*0.6 -> 1053.4426 | J36: =I36*E36 -> 12641.311 | K36: =IF(J36-F36>0,J36-F36,"none") -> none | L36: =IFERROR(ROUNDUP(K36/(D36-0.5),0),"") | M36: =(IF(L36<$Q$5,$O$5,IF(L36<$Q$6,$O$6,IF(L36<$Q$7,$O$7,IF(L36<$Q$8,$O$8,IF(L36<$Q$9,$O$9,IF(L36<$Q$10,$O$10,""))))))) | N36: =I36/D36 -> 61.967213 | O36: =(IF(N36<$P$14,$O$14,IF(N36<$P$15,$O$15,IF(N36<$P$16,$O$16,IF(N36<$P$17,$O$17,IF(N36<$P$18,$O$18,IF(N36<$P$19,$O$19,""))))))) -> 1 | P36: {=$J$13*D36/SUM($C$34:$C$37*$D$34:$D$37)} -> 4832.459 | Q36: =P36*0.7 -> 3382.7213 | R36: =Q36*E36 -> 40592.656 | S36: =IF(R36-F36>0,R36-F36,"none") -> 19784.656 | T36: =IFERROR(ROUNDUP(S36/(D36-0.5),0),"") -> 1200 | U36: =(IF(T36<$Q$5,$O$5,IF(T36<$Q$6,$O$6,IF(T36<$Q$7,$O$7,IF(T36<$Q$8,$O$8,IF(T36<$Q$9,$O$9,IF(T36<$Q$10,$O$10,""))))))) -> A | V36: =Q36/D36 -> 198.98361 | W36: =(IF(V36<$Q$14,$O$14,IF(V36<$Q$15,$O$15,IF(V36<$Q$16,$O$16,IF(V36<$Q$17,$O$17,IF(V36<$Q$18,$O$18,IF(V36<$Q$19,$O$19,""))))))) -> 1 | X36: 3 | Y36: =IF(AND(X36=1,N36>$W$5),"drag",IF(AND(X36=3,N36>$Y$5),"drag",IF(AND(X36=1,V36>$V$5),"drag",IF(AND(X36=3,V36>$X$5),"drag","")))) -> drag
B37: EW-WL2.4 | C37: 1 | D37: 16.5 | E37: 12 | F37: =0.6*$G$6*E37*D37*D37/2 -> 19602 | H37: {=$H$13*D37/SUM($C$34:$C$37*$D$34:$D$37)} -> 1704.0984 | I37: =H37*0.6 -> 1022.459 | J37: =I37*E37 -> 12269.508 | K37: =IF(J37-F37>0,J37-F37,"none") -> none | L37: =IFERROR(ROUNDUP(K37/(D37-0.5),0),"") | M37: =(IF(L37<$Q$5,$O$5,IF(L37<$Q$6,$O$6,IF(L37<$Q$7,$O$7,IF(L37<$Q$8,$O$8,IF(L37<$Q$9,$O$9,IF(L37<$Q$10,$O$10,""))))))) | N37: =I37/D37 -> 61.967213 | O37: =(IF(N37<$P$14,$O$14,IF(N37<$P$15,$O$15,IF(N37<$P$16,$O$16,IF(N37<$P$17,$O$17,IF(N37<$P$18,$O$18,IF(N37<$P$19,$O$19,""))))))) -> 1 | P37: {=$J$13*D37/SUM($C$34:$C$37*$D$34:$D$37)} -> 4690.3279 | Q37: =P37*0.7 -> 3283.2295 | R37: =Q37*E37 -> 39398.754 | S37: =IF(R37-F37>0,R37-F37,"none") -> 19796.754 | T37: =IFERROR(ROUNDUP(S37/(D37-0.5),0),"") -> 1238 | U37: =(IF(T37<$Q$5,$O$5,IF(T37<$Q$6,$O$6,IF(T37<$Q$7,$O$7,IF(T37<$Q$8,$O$8,IF(T37<$Q$9,$O$9,IF(T37<$Q$10,$O$10,""))))))) -> A | V37: =Q37/D37 -> 198.98361 | W37: =(IF(V37<$Q$14,$O$14,IF(V37<$Q$15,$O$15,IF(V37<$Q$16,$O$16,IF(V37<$Q$17,$O$17,IF(V37<$Q$18,$O$18,IF(V37<$Q$19,$O$19,""))))))) -> 1 | X37: 3 | Y37: =IF(AND(X37=1,N37>$W$5),"drag",IF(AND(X37=3,N37>$Y$5),"drag",IF(AND(X37=1,V37>$V$5),"drag",IF(AND(X37=3,V37>$X$5),"drag","")))) -> drag
B38: EW-WL3.1 | C38: 1 | D38: 7.5 | E38: 12 | F38: =0.6*$G$6*E38*D38*D38/2 -> 4050 | H38: {=$H$14*D38/SUM($C$38:$C$41*$D$38:$D$41)} -> 901.59011 | I38: =H38*0.6 -> 540.95406 | J38: =I38*E38 -> 6491.4488 | K38: =IF(J38-F38>0,J38-F38,"none") -> 2441.4488 | L38: =IFERROR(ROUNDUP(K38/(D38-0.5),0),"") -> 349 | M38: =(IF(L38<$Q$5,$O$5,IF(L38<$Q$6,$O$6,IF(L38<$Q$7,$O$7,IF(L38<$Q$8,$O$8,IF(L38<$Q$9,$O$9,IF(L38<$Q$10,$O$10,""))))))) -> A | N38: =I38/D38 -> 72.127208 | O38: =(IF(N38<$P$14,$O$14,IF(N38<$P$15,$O$15,IF(N38<$P$16,$O$16,IF(N38<$P$17,$O$17,IF(N38<$P$18,$O$18,IF(N38<$P$19,$O$19,""))))))) -> 1 | P38: {=$J$14*D38/SUM($C$38:$C$41*$D$38:$D$41)} -> 2481.5194 | Q38: =P38*0.7 -> 1737.0636 | R38: =Q38*E38 -> 20844.763 | S38: =IF(R38-F38>0,R38-F38,"none") -> 16794.763 | T38: =IFERROR(ROUNDUP(S38/(D38-0.5),0),"") -> 2400 | U38: =(IF(T38<$Q$5,$O$5,IF(T38<$Q$6,$O$6,IF(T38<$Q$7,$O$7,IF(T38<$Q$8,$O$8,IF(T38<$Q$9,$O$9,IF(T38<$Q$10,$O$10,""))))))) -> B | V38: =Q38/D38 -> 231.60848 | W38: =(IF(V38<$Q$14,$O$14,IF(V38<$Q$15,$O$15,IF(V38<$Q$16,$O$16,IF(V38<$Q$17,$O$17,IF(V38<$Q$18,$O$18,IF(V38<$Q$19,$O$19,""))))))) -> 1 | X38: 3 | Y38: =IF(AND(X38=1,N38>$W$5),"drag",IF(AND(X38=3,N38>$Y$5),"drag",IF(AND(X38=1,V38>$V$5),"drag",IF(AND(X38=3,V38>$X$5),"drag","")))) -> drag
B39: EW-WL3.2 | C39: 1 | D39: 13.5 | E39: 16 | F39: =0.6*$G$6*E39*D39*D39/2 -> 17496 | H39: {=$H$14*D39/SUM($C$38:$C$41*$D$38:$D$41)} -> 1622.8622 | I39: =H39*0.6 -> 973.71731 | J39: =I39*E39 -> 15579.477 | K39: =IF(J39-F39>0,J39-F39,"none") -> none | L39: =IFERROR(ROUNDUP(K39/(D39-0.5),0),"") | M39: =(IF(L39<$Q$5,$O$5,IF(L39<$Q$6,$O$6,IF(L39<$Q$7,$O$7,IF(L39<$Q$8,$O$8,IF(L39<$Q$9,$O$9,IF(L39<$Q$10,$O$10,""))))))) | N39: =I39/D39 -> 72.127208 | O39: =(IF(N39<$P$14,$O$14,IF(N39<$P$15,$O$15,IF(N39<$P$16,$O$16,IF(N39<$P$17,$O$17,IF(N39<$P$18,$O$18,IF(N39<$P$19,$O$19,""))))))) -> 1 | P39: {=$J$14*D39/SUM($C$38:$C$41*$D$38:$D$41)} -> 4466.735 | Q39: =P39*0.7 -> 3126.7145 | R39: =Q39*E39 -> 50027.432 | S39: =IF(R39-F39>0,R39-F39,"none") -> 32531.432 | T39: =IFERROR(ROUNDUP(S39/(D39-0.5),0),"") -> 2503 | U39: =(IF(T39<$Q$5,$O$5,IF(T39<$Q$6,$O$6,IF(T39<$Q$7,$O$7,IF(T39<$Q$8,$O$8,IF(T39<$Q$9,$O$9,IF(T39<$Q$10,$O$10,""))))))) -> B | V39: =Q39/D39 -> 231.60848 | W39: =(IF(V39<$Q$14,$O$14,IF(V39<$Q$15,$O$15,IF(V39<$Q$16,$O$16,IF(V39<$Q$17,$O$17,IF(V39<$Q$18,$O$18,IF(V39<$Q$19,$O$19,""))))))) -> 1 | X39: 3 | Y39: =IF(AND(X39=1,N39>$W$5),"drag",IF(AND(X39=3,N39>$Y$5),"drag",IF(AND(X39=1,V39>$V$5),"drag",IF(AND(X39=3,V39>$X$5),"drag","")))) -> drag
B40: EW-WL3.3 | C40: 1 | D40: 17.5 | E40: 16 | F40: =0.6*$G$6*E40*D40*D40/2 -> 29400 | H40: {=$H$14*D40/SUM($C$38:$C$41*$D$38:$D$41)} -> 2103.7102 | I40: =H40*0.6 -> 1262.2261 | J40: =I40*E40 -> 20195.618 | K40: =IF(J40-F40>0,J40-F40,"none") -> none | L40: =IFERROR(ROUNDUP(K40/(D40-0.5),0),"") | M40: =(IF(L40<$Q$5,$O$5,IF(L40<$Q$6,$O$6,IF(L40<$Q$7,$O$7,IF(L40<$Q$8,$O$8,IF(L40<$Q$9,$O$9,IF(L40<$Q$10,$O$10,""))))))) | N40: =I40/D40 -> 72.127208 | O40: =(IF(N40<$P$14,$O$14,IF(N40<$P$15,$O$15,IF(N40<$P$16,$O$16,IF(N40<$P$17,$O$17,IF(N40<$P$18,$O$18,IF(N40<$P$19,$O$19,""))))))) -> 1 | P40: {=$J$14*D40/SUM($C$38:$C$41*$D$38:$D$41)} -> 5790.212 | Q40: =P40*0.7 -> 4053.1484 | R40: =Q40*E40 -> 64850.375 | S40: =IF(R40-F40>0,R40-F40,"none") -> 35450.375 | T40: =IFERROR(ROUNDUP(S40/(D40-0.5),0),"") -> 2086 | U40: =(IF(T40<$Q$5,$O$5,IF(T40<$Q$6,$O$6,IF(T40<$Q$7,$O$7,IF(T40<$Q$8,$O$8,IF(T40<$Q$9,$O$9,IF(T40<$Q$10,$O$10,""))))))) -> B | V40: =Q40/D40 -> 231.60848 | W40: =(IF(V40<$Q$14,$O$14,IF(V40<$Q$15,$O$15,IF(V40<$Q$16,$O$16,IF(V40<$Q$17,$O$17,IF(V40<$Q$18,$O$18,IF(V40<$Q$19,$O$19,""))))))) -> 1 | X40: 3 | Y40: =IF(AND(X40=1,N40>$W$5),"drag",IF(AND(X40=3,N40>$Y$5),"drag",IF(AND(X40=1,V40>$V$5),"drag",IF(AND(X40=3,V40>$X$5),"drag","")))) -> drag
B41: EW-WL3.4 | C41: 1 | D41: =8+8/12 -> 8.6666667 | E41: 12 | F41: =0.6*$G$6*E41*D41*D41/2 -> 5408 | H41: {=$H$14*D41/SUM($C$38:$C$41*$D$38:$D$41)} -> 1041.8375 | I41: =H41*0.6 -> 625.10247 | J41: =I41*E41 -> 7501.2297 | K41: =IF(J41-F41>0,J41-F41,"none") -> 2093.2297 | L41: =IFERROR(ROUNDUP(K41/(D41-0.5),0),"") -> 257 | M41: =(IF(L41<$Q$5,$O$5,IF(L41<$Q$6,$O$6,IF(L41<$Q$7,$O$7,IF(L41<$Q$8,$O$8,IF(L41<$Q$9,$O$9,IF(L41<$Q$10,$O$10,""))))))) -> A | N41: =I41/D41 -> 72.127208 | O41: =(IF(N41<$P$14,$O$14,IF(N41<$P$15,$O$15,IF(N41<$P$16,$O$16,IF(N41<$P$17,$O$17,IF(N41<$P$18,$O$18,IF(N41<$P$19,$O$19,""))))))) -> 1 | P41: {=$J$14*D41/SUM($C$38:$C$41*$D$38:$D$41)} -> 2867.5336 | Q41: =P41*0.7 -> 2007.2735 | R41: =Q41*E41 -> 24087.282 | S41: =IF(R41-F41>0,R41-F41,"none") -> 18679.282 | T41: =IFERROR(ROUNDUP(S41/(D41-0.5),0),"") -> 2288 | U41: =(IF(T41<$Q$5,$O$5,IF(T41<$Q$6,$O$6,IF(T41<$Q$7,$O$7,IF(T41<$Q$8,$O$8,IF(T41<$Q$9,$O$9,IF(T41<$Q$10,$O$10,""))))))) -> B | V41: =Q41/D41 -> 231.60848 | W41: =(IF(V41<$Q$14,$O$14,IF(V41<$Q$15,$O$15,IF(V41<$Q$16,$O$16,IF(V41<$Q$17,$O$17,IF(V41<$Q$18,$O$18,IF(V41<$Q$19,$O$19,""))))))) -> 1 | X41: 3 | Y41: =IF(AND(X41=1,N41>$W$5),"drag",IF(AND(X41=3,N41>$Y$5),"drag",IF(AND(X41=1,V41>$V$5),"drag",IF(AND(X41=3,V41>$X$5),"drag","")))) -> drag
