Workbook

Sheet Dashboard
A1: Kingdom Structural — AR Dashboard
A2: Updated: May 7, 2026 | Re-paste data from Novo into 'All Invoices' tab to refresh
A4: TOTAL OUTSTANDING | C4: OVERDUE | E4: NOT YET DUE
A5: =SUMIF('All Invoices'!D5:D60,"Due",'All Invoices'!F5:F60)+SUMIF('All Invoices'!D5:D60,"Overdue",'All Invoices'!F5:F60) -> 151212.82 | C5: =SUMIF('All Invoices'!D5:D60,"Overdue",'All Invoices'!F5:F60) -> 55223.84 | E5: =SUMIF('All Invoices'!D5:D60,"Due",'All Invoices'!F5:F60) -> 95988.98
A8: AGING BUCKET BREAKDOWN
A9: Bucket | B9: $ Total | C9: # Invoices | D9: % of AR
A10: Not yet due | B10: =SUMIF('All Invoices'!G5:G60,"Not yet due",'All Invoices'!F5:F60) -> 95988.98 | C10: =COUNTIF('All Invoices'!G5:G60,"Not yet due") -> 29 | D10: =B10/$A$5 -> 0.63479393
A11: 1-30 days | B11: =SUMIF('All Invoices'!G5:G60,"1-30 days",'All Invoices'!F5:F60) -> 31033.24 | C11: =COUNTIF('All Invoices'!G5:G60,"1-30 days") -> 15 | D11: =B11/$A$5 -> 0.2052289
A12: 31-60 days | B12: =SUMIF('All Invoices'!G5:G60,"31-60 days",'All Invoices'!F5:F60) -> 16790.6 | C12: =COUNTIF('All Invoices'!G5:G60,"31-60 days") -> 9 | D12: =B12/$A$5 -> 0.11103953
A13: 61-90 days | B13: =SUMIF('All Invoices'!G5:G60,"61-90 days",'All Invoices'!F5:F60) -> 1200 | C13: =COUNTIF('All Invoices'!G5:G60,"61-90 days") -> 1 | D13: =B13/$A$5 -> 0.0079358351
A14: 90+ days | B14: =SUMIF('All Invoices'!G5:G60,"90+ days",'All Invoices'!F5:F60) -> 6200 | C14: =COUNTIF('All Invoices'!G5:G60,"90+ days") -> 1 | D14: =B14/$A$5 -> 0.041001815
A17: DSO (Days Sales Outstanding)
A18: Annual revenue (input — pull from books) | B18: 1000000
A19: Outstanding AR | B19: =A5 -> 151212.82
A20: DSO | B20: =(B19/B18)*365 -> 55.192679
A21: Industry benchmark (engineering): 35-50 days good, 50-65 average, 65+ concerning
A23: TOP CONCERNS — work today
A24: Marcellus & Associates inv #0282 | B24: $6,200 — 123 days overdue. CALL TODAY.
A25: CMDA Design Bureau inv #0309 | B25: $1,200 — 70 days overdue. CALL TODAY.
A26: Ramon Design Group | B26: 5 invoices, $7,500 overdue. Pattern client — Net 15 going forward.
A27: FFKR Architects | B27: $9,300 overdue + $10,822 unpaid. One phone call covers all.
A28: United Structural Design LLC | B28: WHALE: $25,200 unpaid coming due + $2,130 already overdue.
A29: Asset Living | B29: 5 invoices, $4,462 overdue. Same pattern — change terms.
A32: TAB GUIDE
A33: Dashboard | B33: This page — top-line metrics and concerns
A34: Collections | B34: Prioritized action list — work top to bottom
A35: All Invoices | B35: Master list of every open invoice. Update by re-pasting Novo export.
A36: Aging by Client | B36: Pivot showing total owed per client across aging buckets
A37: Activity Log | B37: Track every collection action: when contacted, response, next step
A38: DSO Tracker | B38: Monthly DSO log — see trend over time
A39: Playbook | B39: Standard AR process and timing reference

Sheet Collections
A1: ACCOUNTS RECEIVABLE — collections priority
A2: Total outstanding ≈ $151,213. Overdue ≈ $55,224. Source: Novo as of May 7, 2026.
A4: AR SUMMARY
A5: Total outstanding | B5: 151213 | C5: 29 unpaid + 26 overdue
A6: Overdue 90+ days (P0) | B6: 6200 | C6: 1 invoice
A7: Overdue 60-90 days (P0) | B7: 1200 | C7: 1 invoice
A8: Overdue 30-60 days (P1) | B8: 16940 | C8: 9 invoices
A9: Overdue 1-30 days (P2) | B9: 30884 | C9: 15 invoices
A10: Not yet due (watch) | B10: 95989 | C10: 29 invoices
A12: OVERDUE INVOICES — work top to bottom
A13: Priority | B13: Invoice | C13: Client | D13: Issue Date | E13: Days Late | F13: Amount | G13: Bucket | H13: Action
A14: P0 | B14: #0264 | C14: United Structural Design LLC | D14: 46020 | E14: 124 | F14: 1500 | G14: 90+
A15: P0 | B15: #0282 | C15: Marcellus & Associates | D15: 46023 | E15: 101 | F15: 6200 | G15: 90+ | H15: CALL TODAY. Collections agency in 7 days if no response.
A16: P0 | B16: #0308 | C16: CMDA Design Bureau | D16: Jan 26 | E16: 70 | F16: 1200 | G16: 60-90 | H16: CALL TODAY. Final notice email.
B17: #0314 | C17: Ramon Design Group | D17: 46056 | E17: 68 | F17: 4400 | G17: 60-90
A18: P1 | B18: #0323 | C18: Marcellus & Associates | D18: Feb 12 | E18: 54 | F18: 2800 | G18: 30-60 | H18: Phone + 3rd notice this week
A19: P1 | B19: #0327 | C19: Ramon Design Group | D19: Feb 19 | E19: 47 | F19: 800 | G19: 30-60 | H19: 3rd notice
A20: P1 | B20: #0328 | C20: AX3 Construction | D20: Feb 19 | E20: 47 | F20: 150 | G20: 30-60 | H20: 3rd notice
A21: P1 | B21: #0294 | C21: Designtank | D21: 46107 | E21: 17 | F21: 3465 | G21: 30-60 | H21: Phone
A22: P1 | B22: #0317 | C22: Flag Ranch Self Storage | D22: Feb 22 | E22: 44 | F22: 2000 | G22: 30-60 | H22: Phone + 3rd notice
A23: P1 | B23: #0330 | C23: Ramon Design Group | D23: Feb 24 | E23: 42 | F23: 800 | G23: 30-60 | H23: 3rd notice
A24: P1 | B24: #0340 | C24: Asset Living | D24: Feb 26 | E24: 40 | F24: 1940.6 | G24: 30-60 | H24: 3rd notice
A25: P1 | B25: #0322 | C25: CHB Architects | D25: Feb 27 | E25: 39 | F25: 3300 | G25: 30-60 | H25: Phone + 3rd notice
A26: P1 | B26: #0342 | C26: Andy Kunasek | D26: Mar 03 | E26: 35 | F26: 600 | G26: 30-60 | H26: 3rd notice
A27: P2 | B27: #0349 | C27: David Garcia Acosta | D27: Mar 10 | E27: 28 | F27: 5000 | G27: 1-30 | H27: 2nd notice — large amount
A28: P2 | B28: #0355 | C28: Thom Vehon | D28: Mar 12 | E28: 26 | F28: 1600 | G28: 1-30 | H28: 2nd notice
A29: P2 | B29: #0357 | C29: United Structural Design LLC | D29: Mar 17 | E29: 21 | F29: 1500 | G29: 1-30 | H29: 2nd notice
A30: P2 | B30: #0358 | C30: United Structural Design LLC | D30: Mar 17 | E30: 21 | F30: 630 | G30: 1-30 | H30: 2nd notice
A31: P2 | B31: #0359 | C31: Ramon Design Group | D31: Mar 20 | E31: 18 | F31: 1500 | G31: 1-30 | H31: 2nd notice — pattern
A32: P2 | B32: #0362 | C32: A & E Design Group LLC | D32: Mar 20 | E32: 18 | F32: 500 | G32: 1-30 | H32: 2nd notice
A33: P2 | B33: #0363 | C33: FFKR Architects | D33: Mar 24 | E33: 14 | F33: 6700 | G33: 1-30 | H33: 2nd notice — LARGEST P2
... A39: P2 | B39: #0381 | C39: CM Associates Engineers | D39: Apr 07 | E39: 1 | F39: 2600 | G39: 1-30 | H39: 1st notice
A41: TOTAL OVERDUE | F41: =SUM(F14:F39) -> 57831.24
A43: REPEAT-OFFENDER CLIENTS
A44: Ramon Design Group | B44: 4 overdue totaling $7,500 — pattern. Net-15 or 25% deposit going forward.
A45: Asset Living | B45: 4 overdue totaling $3,679 — pattern. Same approach.
A46: FFKR Architects | B46: 2 overdue ($9,300) + unpaid ($10,822) — single POC, one phone call.
A47: United Struct Design LLC | B47: 2 overdue ($2,130) + 2 large unpaid ($25,200) — WHALE; careful but firm.
A48: Marcellus & Associates | B48: 2 overdue totaling $9,000 (one 4+ months old) — highest risk; lawyer letter ready.
A51: PROCESS IMPROVEMENTS — fix the leak
...

Sheet All Invoices
A1: ALL OPEN INVOICES — master list
A2: Source: Novo invoice export. Update by re-pasting CSV. As of May 7, 2026.
A4: Invoice | B4: Client | C4: Issue Date | D4: Status | E4: Days | F4: Amount | G4: Aging Bucket | H4: Notes
A5: #0419 | B5: United Structural Design LLC | C5: 2026-05-06 | D5: Due | E5: 29 | F5: 13200 | G5: Not yet due
A6: #0418 | B6: United Structural Design LLC | C6: 2026-05-06 | D6: Due | E6: 29 | F6: 12000 | G6: Not yet due
A7: #0417 | B7: Kirk Development Company | C7: 2026-05-04 | D7: Due | E7: 27 | F7: 515 | G7: Not yet due
A8: #0414 | B8: Designtank | C8: 2026-05-04 | D8: Due | E8: 27 | F8: 4800 | G8: Not yet due
A9: #0413 | B9: Vivian Alaya Lopez | C9: 2026-05-05 | D9: Due | E9: 28 | F9: 1800 | G9: Not yet due
A10: #0412 | B10: Murata Machinery USA Inc | C10: 2026-04-30 | D10: Due | E10: 23 | F10: 616.8 | G10: Not yet due
A11: #0411 | B11: Ramon Design Group | C11: 2026-04-30 | D11: Due | E11: 23 | F11: 1600 | G11: Not yet due
A12: #0410 | B12: Ramon Design Group | C12: 2026-04-30 | D12: Due | E12: 23 | F12: 800 | G12: Not yet due
A13: #0409 | B13: Kevin Jackson | C13: 2026-04-29 | D13: Due | E13: 22 | F13: 3750 | G13: Not yet due
A14: #0408 | B14: ERG, LLC | C14: 2026-04-30 | D14: Due | E14: 23 | F14: 800 | G14: Not yet due
A15: #0407 | B15: Murata Machinery USA Inc | C15: 2026-04-30 | D15: Due | E15: 23 | F15: 1800 | G15: Not yet due
A16: #0406 | B16: JE Fuller Hydrology & Geomorphology | C16: 2026-04-30 | D16: Due | E16: 23 | F16: 1000 | G16: Not yet due
... A59: #0282 | B59: Marcellus & Associates | C59: 2026-01-05 | D59: Overdue | E59: 123 | F59: 6200 | G59: 90+ days
A60: TOTAL | F60: =SUM(F5:F59) -> 151212.82

Sheet Aging by Client
A1: AGING BY CLIENT
A2: Each row is a client. Columns are aging buckets. Sorted by total outstanding.
A4: Client | B4: Not yet due | C4: 1-30 days | D4: 31-60 days | E4: 61-90 days | F4: 90+ days | G4: TOTAL | H4: # Inv
A5: United Structural Design LLC | B5: 25200 | C5: 2130 | G5: 27330 | H5: 4
A6: FFKR Architects | B6: 10822.4 | C6: 9300 | G6: 20122.4 | H6: 5
A7: Ramon Design Group | B7: 5600 | C7: 1500 | D7: 6000 | G7: 13100 | H7: 8
A8: D. Alan Roberts | B8: 11000 | G8: 11000 | H8: 1
A9: Marcellus & Associates | D9: 2800 | F9: 6200 | G9: 9000 | H9: 2
A10: Designtank | B10: 4800 | C10: 3465 | G10: 8265 | H10: 2
A11: Krista R Corporations | B11: 6673.84 | G11: 6673.84 | H11: 1
A12: David Garcia Acosta | C12: 5000 | G12: 5000 | H12: 1
A13: Blackbird Design | B13: 4886.2 | G13: 4886.2 | H13: 1
A14: Asset Living | B14: 783.32 | C14: 1738.24 | D14: 1940.6 | G14: 4462.16 | H14: 5
A15: Camden Living | B15: 3900 | G15: 3900 | H15: 1
A16: JE Fuller Hydrology & Geomorphology | B16: 3760 | G16: 3760 | H16: 2
A17: Kevin Jackson | B17: 3750 | G17: 3750 | H17: 1
A18: Kirk Development Company | B18: 2141.6 | C18: 1400 | G18: 3541.6 | H18: 3
A19: CHB Architects | D19: 3300 | G19: 3300 | H19: 1
A20: AHGUEST | B20: 3000 | G20: 3000 | H20: 1
A21: Speedwell Construction INC | B21: 2800 | G21: 2800 | H21: 2
A22: CM Associates Engineers PLLC | C22: 2600 | G22: 2600 | H22: 1
A23: Murata Machinery USA Inc | B23: 2416.8 | G23: 2416.8 | H23: 2
A24: Flag Ranch Self Storage | D24: 2000 | G24: 2000 | H24: 1
A25: Vivian Alaya Lopez | B25: 1800 | G25: 1800 | H25: 1
A26: Global Construction | C26: 1800 | G26: 1800 | H26: 1
A27: Thom Vehon | C27: 1600 | G27: 1600 | H27: 1
A28: CMDA Design Bureau | E28: 1200 | G28: 1200 | H28: 1
A29: Trevor Pan Architects | B29: 1160 | G29: 1160 | H29: 1
A30: ERG, LLC | B30: 800 | G30: 800 | H30: 1
A31: D&E Services Inc | B31: 694.82 | G31: 694.82 | H31: 1
A32: Andy Kunasek | D32: 600 | G32: 600 | H32: 1
A33: A & E Design Group LLC | C33: 500 | G33: 500 | H33: 1
A34: AX3 Construction | D34: 150 | G34: 150 | H34: 1
A35: TOTAL | B35: =SUM(B5:B34) -> 95988.98 | C35: =SUM(C5:C34) -> 31033.24 | D35: =SUM(D5:D34) -> 16790.6 | E35: =SUM(E5:E34) -> 1200 | F35: =SUM(F5:F34) -> 6200 | G35: =SUM(G5:G34) -> 151212.82 | H35: =SUM(H5:H34) -> 55

Sheet Activity Log
A1: ACTIVITY LOG
A2: Track every collection touchpoint: when, who, what was said, response, next step. Append rows as you go.
A4: Date | B4: Invoice # | C4: Client | D4: Action Type | E4: Contact Method | F4: Outcome | G4: Promised Pay Date | H4: Next Step / Owner
A5: EXAMPLE → | B5: #0282 | C5: Marcellus & Associates | D5: Phone call | E5: Phone | F5: Promised by date | G5: 2026-05-15 | H5: Send confirmation email today; follow up if not paid by 5/15

Sheet DSO Tracker
A1: DSO TRACKER — monthly trend
A2: Log AR + revenue at month-end. DSO = (AR ÷ Revenue) × 365. Track trend over time.
A4: BENCHMARKS (engineering services)
A5: Excellent | B5: < 35 days | C5: Best-in-class collection process
A6: Good | B6: 35-50 days | C6: Industry standard
A7: Average | B7: 50-65 days | C7: Most engineering firms
A8: Concerning | B8: 65-85 days | C8: AR process needs work
A9: Crisis | B9: 85+ days | C9: Restructure terms / late fees / deposits
A11: MONTHLY LOG
A12: Month-End | B12: Outstanding AR | C12: Trailing 12mo Revenue | D12: DSO (days) | E12: vs. Last Month | F12: Notes
A13: 2026-04-30 | B13: 151213 | C13: 1000000 | D13: =(B13/C13)*365 -> 55.192745 | E13: — | F13: Baseline. Update revenue figure with actual.
D14: =IF(B14>0,(B14/C14)*365,"") | E14: =IF(D14<>"",D14-D13,"")
D15: =IF(B15>0,(B15/C15)*365,"") | E15: =IF(D15<>"",D15-D14,"")
D16: =IF(B16>0,(B16/C16)*365,"") | E16: =IF(D16<>"",D16-D15,"")
D17: =IF(B17>0,(B17/C17)*365,"") | E17: =IF(D17<>"",D17-D16,"")
D18: =IF(B18>0,(B18/C18)*365,"") | E18: =IF(D18<>"",D18-D17,"")
D19: =IF(B19>0,(B19/C19)*365,"") | E19: =IF(D19<>"",D19-D18,"")
D20: =IF(B20>0,(B20/C20)*365,"") | E20: =IF(D20<>"",D20-D19,"")
D21: =IF(B21>0,(B21/C21)*365,"") | E21: =IF(D21<>"",D21-D20,"")
D22: =IF(B22>0,(B22/C22)*365,"") | E22: =IF(D22<>"",D22-D21,"")
D23: =IF(B23>0,(B23/C23)*365,"") | E23: =IF(D23<>"",D23-D22,"")
D24: =IF(B24>0,(B24/C24)*365,"") | E24: =IF(D24<>"",D24-D23,"")
D25: =IF(B25>0,(B25/C25)*365,"") | E25: =IF(D25<>"",D25-D24,"")
... D37: =IF(B37>0,(B37/C37)*365,"") | E37: =IF(D37<>"",D37-D36,"")

Sheet Playbook
A1: AR COLLECTIONS PLAYBOOK
A2: The standard process. Don't deviate without reason.
A4: TIMELINE — what happens when
A5: Day | B5: Action | C5: Method | D5: Template | E5: Owner
A6: Day 0 | B6: Invoice issued | C6: Novo | D6: — | E6: Project lead
A7: Day -3 | B7: Pre-due reminder | C7: Email auto | D7: Template 1 | E7: Auto
A8: Day +1 | B8: 1st overdue notice | C8: Email | D8: Template 2 | E8: AR owner
A9: Day +14 | B9: 2nd overdue notice | C9: Email | D9: Template 3 | E9: AR owner
A10: Day +21 | B10: Phone call | C10: Phone | D10: Phone script | E10: AR owner
A11: Day +30 | B11: 3rd / firm notice | C11: Email | D11: Template 4 | E11: AR owner
A12: Day +45 | B12: Project hold + escalation | C12: Phone+Email | D12: — | E12: Owner / Michael
A13: Day +60 | B13: Final notice (certified mail) | C13: Mail+Email | D13: Template 5 | E13: Owner / Michael
A14: Day +75 | B14: Lawyer letter | C14: Mail | D14: Attorney drafted | E14: Attorney
A15: Day +90 | B15: Collections agency referral | C15: Per agency | D15: — | E15: Attorney
A18: RULES OF ENGAGEMENT
A19: 1. Always document in 'Activity Log'. Within 30 minutes of any call/email.
A20: 2. Never threaten what you won't follow through on.
A21: 3. After any phone commitment: send a confirmation email within 30 minutes recapping date + amount.
A22: 4. If a client says 'check is in the mail' twice without it arriving — escalate immediately.
A23: 5. Repeat offenders (3+ overdue invoices in 12 months) → require 25% deposit OR Net 15 going forward.
A24: 6. Never extend new credit to a client with anything 60+ days overdue. Hold their next project until cleared.
A25: 7. Late fees apply automatically per contract (1.5%/mo). Don't waive without manager approval.
A26: 8. Disputes are different from non-payment. Resolve fast. A disputed invoice is the AR owner's #1 priority.
A27: 9. Don't argue on the phone. Listen, get a commitment, document, escalate if needed.
A30: HOW TO REFRESH THIS WORKBOOK
A31: 1. Log into Novo → Invoices → filter to Unpaid.
... A38: 8. Update DSO Tracker monthly — log AR + revenue at each month-end.
