Workbook

Sheet Dashboard
A1: Kingdom Structural — 2027 Budget Dashboard
A2: 25/75 model. Subconsultants moved to comp pool. Placeholder lines have realistic 2027 baselines (yellow fill in '2027 Budget' tab).
A4: REVENUE | C4: OVERHEAD | E4: COMP POOL
A5: ='2027 Budget'!G10 -> 718451.07 | C5: ='2027 Budget'!G26 -> 115710.3 | E5: ='2027 Budget'!G29 -> 602740.77
C7: ='2027 Budget'!H26 -> 0.16105522 | E7: ='2027 Budget'!H29 -> 0.83894478
A9: 25/75 HEALTH CHECK
A10: Metric | B10: 2027 Forecast | C10: Target | D10: Status | E10: Detail
A11: Overhead % | B11: ='2027 Budget'!H26 -> 0.16105522 | C11: ≤ 25% | D11: =IF(B11<=0.25,"PASS","FAIL") -> PASS | E11: =IF(B11<=0.25,"Operating efficient","Trim overhead") -> Operating efficient
A12: Comp Pool % | B12: ='2027 Budget'!H29 -> 0.83894478 | C12: ≥ 70% | D12: =IF(B12>=0.7,"PASS","FAIL") -> PASS | E12: =IF(B12>=0.7,"Healthy","Overhead squeezing pool") -> Healthy
A13: JB K1 Annual | B13: ='2027 Budget'!E42 -> 120548.15 | C13: $150-200k | D13: =IF(AND(B13>=150000,B13<=200000),"IN RANGE",IF(B13<150000,"BELOW","ABOVE")) -> BELOW | E13: =IF(B13<150000,"Need more rev / less expense / less W2 alloc","") -> Need more rev / less expense / less W2 alloc
A14: CV K1 Annual | B14: ='2027 Budget'!E43 -> 120548.15 | C14: $150-200k | D14: =IF(AND(B14>=150000,B14<=200000),"IN RANGE",IF(B14<150000,"BELOW","ABOVE")) -> BELOW | E14: =IF(B14<150000,"Need more rev / less expense / less W2 alloc","") -> Need more rev / less expense / less W2 alloc
A16: POOL ALLOCATION (5 LINES)
A17: Category | B17: % of Pool | C17: $ Amount | D17: % of Revenue | E17: Notes
A18: W2 Payroll (Engineers + Drafters) | B18: ='2027 Budget'!F33 -> 0.4 | C18: ='2027 Budget'!G33 -> 241096.31 | D18: ='2027 Budget'!H33 -> 0.33557791 | E18: Salary + payroll tax for staff
A19: Contract Work (1099) | B19: ='2027 Budget'!F34 -> 0.05 | C19: ='2027 Budget'!G34 -> 30137.038 | D19: ='2027 Budget'!H34 -> 0.041947239 | E19: Sub-engineers/drafters on staff aug basis
A20: Subconsultants / 3PD | B20: ='2027 Budget'!F35 -> 0.05 | C20: ='2027 Budget'!G35 -> 30137.038 | D20: ='2027 Budget'!H35 -> 0.041947239 | E20: Project-delivery support — moved from overhead
A21: Commissions + Bonuses | B21: ='2027 Budget'!F36 -> 0.1 | C21: ='2027 Budget'!G36 -> 60274.077 | D21: ='2027 Budget'!H36 -> 0.083894478 | E21: Performance pay through Paylocity
A22: Partner K1 (RESIDUAL) | B22: ='2027 Budget'!F37 -> 0.4 | C22: ='2027 Budget'!G37 -> 241096.31 | D22: ='2027 Budget'!H37 -> 0.33557791 | E22: What's left after staff/comm/sub paid
A24: STRATEGIC NOTES
A25: Subconsultants/3PD now in comp pool (was overhead). Cleaner — they're project-delivery, not overhead. Net K1 is unchanged; just better categorization.
A26: Placeholder overhead lines now have realistic 2027 baselines (yellow fill cells in '2027 Budget'): Insurance $15k, Memberships $3.5k, Benefits $10k, Travel $5k, Supplies $2k, Income Tax $5k.
A27: Total realistic overhead: ~$118-120k (~17% of revenue) — well under 25% cap. The headroom (~8%) flows to comp pool.
A28: K1 distribution paid quarterly, performance-based. NOT equity-driven. Adjust % split in '2027 Budget' to actual work share.
A29: If JB or CV K1 shows BELOW: grow revenue, cut overhead lines, or reduce W2/contract allocation %.
A30: AR collections directly increase comp pool. $55k overdue + $96k unpaid = potential +$50-150k to pool when collected.

Sheet 2027 Budget
A1: KINGDOM STRUCTURAL — 2027 BUDGET
A2: 25/75 model: ≤25% revenue→overhead, 75% revenue→comp pool. Yellow cells = 2027 baseline estimates (placeholder lines with no 2026 spend).
A4: GL Code | B4: Category | C4: 2026 YTD | D4: Months | E4: 2026 Ann. / 2027 Base | F4: Adj % | G4: 2027 Forecast | H4: % of Rev
A5: REVENUE
A6: 9003 | B6: Invoice | C6: 259202.39 | D6: 5 | E6: 622085.74 | F6: 0.15 | G6: =E6*(1+F6) -> 715398.6
A7: 9005 | B7: Reimbursement | C7: 0 | D7: 0 | E7: 0 | F7: 0.1 | G7: =E7*(1+F7) -> 0
A8: 9004 | B8: Survey Payment | C8: 0 | D8: 0 | E8: 0 | F8: 0 | G8: =E8*(1+F8) -> 0
A9: 9001 | B9: Refund | C9: 1017.49 | D9: 4 | E9: 3052.47 | F9: 0 | G9: =E9*(1+F9) -> 3052.47
B10: TOTAL REVENUE | E10: =SUM(E6:E9) -> 625138.21 | G10: =SUM(G6:G9) -> 718451.07
A12: OVERHEAD (TARGET ≤ 25% OF REVENUE)
A13: 1001 | B13: Rent-Office Spaces | C13: 7348.77 | D13: 5 | E13: 17637.048 | F13: 0.03 | G13: =E13*(1+F13) -> 18166.159 | H13: =IFERROR(G13/$G$10,0) -> 0.025285173
A14: 1003 | B14: Business License | C14: 1763.2 | D14: 5 | E14: 4231.68 | F14: 0.05 | G14: =E14*(1+F14) -> 4443.264 | H14: =IFERROR(G14/$G$10,0) -> 0.0061845047
A15: 1004 | B15: Employee Benefits (health, etc.) | C15: 0 | D15: 0 | E15: 10000 | F15: 0 | G15: =E15*(1+F15) -> 10000 | H15: =IFERROR(G15/$G$10,0) -> 0.013918832
A16: 1005 | B16: Insurance (E&O, GL, Auto) | C16: 0 | D16: 0 | E16: 15000 | F16: 0 | G16: =E16*(1+F16) -> 15000 | H16: =IFERROR(G16/$G$10,0) -> 0.020878249
A17: 1006 | B17: Memberships (AISC, NCEES) | C17: 0 | D17: 0 | E17: 3500 | F17: 0 | G17: =E17*(1+F17) -> 3500 | H17: =IFERROR(G17/$G$10,0) -> 0.0048715913
A18: 1008 | B18: Software | C18: 8447.79 | D18: 5 | E18: 20274.696 | F18: 0.05 | G18: =E18*(1+F18) -> 21288.431 | H18: =IFERROR(G18/$G$10,0) -> 0.02963101
A19: 2004 | B19: Meal | C19: 80.34 | D19: 1 | E19: 964.08 | F19: 0.05 | G19: =E19*(1+F19) -> 1012.284 | H19: =IFERROR(G19/$G$10,0) -> 0.0014089811
A20: 2005 | B20: Outside Professional Services (CPA, Atty) | C20: 2800 | D20: 2 | E20: 16800 | F20: 0.05 | G20: =E20*(1+F20) -> 17640 | H20: =IFERROR(G20/$G$10,0) -> 0.02455282
A21: 2006 | B21: Taxes and Licenses | C21: 751.93 | D21: 2 | E21: 4511.58 | F21: 0.05 | G21: =E21*(1+F21) -> 4737.159 | H21: =IFERROR(G21/$G$10,0) -> 0.0065935722
A22: 2007 | B22: Office Expenses | C22: 2641 | D22: 4 | E22: 7923 | F22: 0 | G22: =E22*(1+F22) -> 7923 | H22: =IFERROR(G22/$G$10,0) -> 0.011027891
A23: 2008 | B23: Office Supplies | C23: 0 | D23: 0 | E23: 2000 | F23: 0 | G23: =E23*(1+F23) -> 2000 | H23: =IFERROR(G23/$G$10,0) -> 0.0027837665
A24: 2010 | B24: Income Tax (firm) | C24: 0 | D24: 0 | E24: 5000 | F24: 0 | G24: =E24*(1+F24) -> 5000 | H24: =IFERROR(G24/$G$10,0) -> 0.0069594162
A25: 2011 | B25: Travel & Transportation | C25: 0 | D25: 0 | E25: 5000 | F25: 0 | G25: =E25*(1+F25) -> 5000 | H25: =IFERROR(G25/$G$10,0) -> 0.0069594162
B26: TOTAL OVERHEAD | C26: =SUM(C13:C25) -> 23833.03 | E26: =SUM(E13:E25) -> 112842.08 | G26: =SUM(G13:G25) -> 115710.3 | H26: =G26/$G$10 -> 0.16105522
A28: PERFORMANCE COMP POOL (= REVENUE − OVERHEAD, TARGET ~75% OF REVENUE)
B29: Performance Comp Pool $ | G29: =G10-G26 -> 602740.77 | H29: =G29/$G$10 -> 0.83894478
A31: POOL ALLOCATION
A32: GL | B32: Allocation | C32: 2026 YTD | D32: Months | E32: 2026 Ann. | F32: % of Pool | G32: 2027 $ Forecast | H32: % of Rev
A33: 3002+ | B33: W2 Payroll (engineers + drafters + payroll tax) | C33: 80252.587 | D33: 4 | E33: 240757.76 | F33: 0.4 | G33: =$G$29*F33 -> 241096.31 | H33: =G33/$G$10 -> 0.33557791
A34: 2002 | B34: Contract Work (1099 sub-engineers/drafters) | C34: 7606.75 | D34: 1 | E34: 91281 | F34: 0.05 | G34: =$G$29*F34 -> 30137.038 | H34: =G34/$G$10 -> 0.041947239
A35: 3001 | B35: Subconsultants / 3PD (project delivery support) | C35: 0 | D35: 0 | E35: 0 | F35: 0.05 | G35: =$G$29*F35 -> 30137.038 | H35: =G35/$G$10 -> 0.041947239
A36: 3004/05 | B36: Commissions + Bonuses | C36: 13181.22 | D36: 2 | E36: 79087.32 | F36: 0.1 | G36: =$G$29*F36 -> 60274.077 | H36: =G36/$G$10 -> 0.083894478
A37: 5001/02 | B37: Partner K1 Distributions (RESIDUAL) | C37: 85264.98 | D37: 2 | E37: 718744.92 | F37: =1-F33-F34-F35-F36 -> 0.4 | G37: =$G$29-G33-G34-G35-G36 -> 241096.31 | H37: =G37/$G$10 -> 0.33557791
B38: Total Allocation | F38: =SUM(F33:F37) -> 1 | G38: =SUM(G33:G37) -> 602740.77 | H38: =G38/$G$10 -> 0.83894478
A40: K1 SPLIT (PERFORMANCE-BASED, NOT EQUITY)
B41: Partner | C41: % Split | E41: Annual K1 | G41: Per Quarter | H41: vs $150-200k
A42: 5001 | B42: JB | C42: 0.5 | E42: =$G$37*C42 -> 120548.15 | G42: =E42/4 -> 30137.038 | H42: =IF(E42>=150000,IF(E42<=200000,"In range","Above"),"Below") -> Below
A43: 5002 | B43: CV | C43: 0.5 | E43: =$G$37*C43 -> 120548.15 | G43: =E43/4 -> 30137.038 | H43: =IF(E43>=150000,IF(E43<=200000,"In range","Above"),"Below") -> Below
B44: Total K1 | C44: =SUM(C42:C43) -> 1 | E44: =SUM(E42:E43) -> 241096.31 | G44: =SUM(G42:G43) -> 60274.077
A46: HEALTH CHECKS
...

Sheet Methodology
A1: How this workbook works
A3: 25/75 Model | B3: Kingdom's strategic split: ≤25% revenue → overhead. 75%+ revenue → performance comp pool. Net retained = $0.
A4: Overhead | B4: Sum of forecast lines (rent, software, insurance, memberships, etc.). Health check flags if total exceeds 25%.
A5: Subconsultants moved to pool | B5: GL 3001 reclassified from overhead to comp pool — they're project-delivery support, not overhead. Cleaner reporting.
A6: Yellow baseline cells | B6: Lines with no 2026 spend (Insurance, Memberships, Benefits, Travel, Supplies, Income Tax) have realistic 2027 baseline estimates instead of $0. Edit these directly to fine-tune.
A7: Comp Pool | B7: Pool $ = Revenue minus Overhead. Should land at ≥70% of revenue.
A8: Pool Allocation | B8: 5 lines: W2 (40%), Contract (5%), Subconsultants (5%), Commissions+Bonus (10%), Partner K1 (RESIDUAL = 40%). First four are inputs; K1 is what's left.
A9: Partner K1 | B9: Quarterly, performance-based. Edit % split in '2027 Budget' (column C of K1 SPLIT section) to reflect actual work share each partner delivered.
A10: Annualization caveat | B10: 2026 YTD covers Jan-May only. Lines with low months_active show inflated annualizations. Adjust Adj % to true things up.
A11: Refresh process | B11: Manual until Mercury automation goes live. Paste new YTD numbers into column C/D/E of '2027 Budget' as 2026 progresses.
